[2021-04-25 16:43:01,637: ERROR/MainProcess] consumer: Cannot connect to amqp://guest:**@127.0.0.1:5672//: [Errno 111] Connection refused.
Trying again in 2.00 seconds... (1/100)

[2021-04-25 16:43:03,655: INFO/MainProcess] Connected to amqp://guest:**@127.0.0.1:5672//
[2021-04-25 16:43:03,668: INFO/MainProcess] mingle: searching for neighbors
[2021-04-25 16:43:04,738: INFO/MainProcess] mingle: all alone
[2021-04-25 16:43:04,773: WARNING/MainProcess] /home/skydata/buy_it/env/lib/python3.8/site-packages/celery/fixups/django.py:205: UserWarning: Using settings.DEBUG leads to a memory
            leak, never use this setting in production environments!
  warnings.warn('''Using settings.DEBUG leads to a memory
[2021-04-25 16:43:04,773: INFO/MainProcess] celery@skydata-Latitude-E5430-non-vPro ready.
[2021-04-25 17:33:16,110: WARNING/MainProcess] consumer: Connection to broker lost. Trying to re-establish the connection...
Traceback (most recent call last):
  File "/home/skydata/buy_it/env/lib/python3.8/site-packages/celery/worker/consumer/consumer.py", line 318, in start
    blueprint.start(self)
  File "/home/skydata/buy_it/env/lib/python3.8/site-packages/celery/bootsteps.py", line 119, in start
    step.start(parent)
  File "/home/skydata/buy_it/env/lib/python3.8/site-packages/celery/worker/consumer/consumer.py", line 599, in start
    c.loop(*c.loop_args())
  File "/home/skydata/buy_it/env/lib/python3.8/site-packages/celery/worker/loops.py", line 83, in asynloop
    next(loop)
  File "/home/skydata/buy_it/env/lib/python3.8/site-packages/kombu/asynchronous/hub.py", line 364, in create_loop
    cb(*cbargs)
  File "/home/skydata/buy_it/env/lib/python3.8/site-packages/kombu/transport/base.py", line 238, in on_readable
    reader(loop)
  File "/home/skydata/buy_it/env/lib/python3.8/site-packages/kombu/transport/base.py", line 220, in _read
    drain_events(timeout=0)
  File "/home/skydata/buy_it/env/lib/python3.8/site-packages/amqp/connection.py", line 508, in drain_events
    while not self.blocking_read(timeout):
  File "/home/skydata/buy_it/env/lib/python3.8/site-packages/amqp/connection.py", line 514, in blocking_read
    return self.on_inbound_frame(frame)
  File "/home/skydata/buy_it/env/lib/python3.8/site-packages/amqp/method_framing.py", line 55, in on_frame
    callback(channel, method_sig, buf, None)
  File "/home/skydata/buy_it/env/lib/python3.8/site-packages/amqp/connection.py", line 520, in on_inbound_method
    return self.channels[channel_id].dispatch_method(
  File "/home/skydata/buy_it/env/lib/python3.8/site-packages/amqp/abstract_channel.py", line 145, in dispatch_method
    listener(*args)
  File "/home/skydata/buy_it/env/lib/python3.8/site-packages/amqp/connection.py", line 649, in _on_close
    self._x_close_ok()
  File "/home/skydata/buy_it/env/lib/python3.8/site-packages/amqp/connection.py", line 664, in _x_close_ok
    self.send_method(spec.Connection.CloseOk, callback=self._on_close_ok)
  File "/home/skydata/buy_it/env/lib/python3.8/site-packages/amqp/abstract_channel.py", line 59, in send_method
    conn.frame_writer(1, self.channel_id, sig, args, content)
  File "/home/skydata/buy_it/env/lib/python3.8/site-packages/amqp/method_framing.py", line 189, in write_frame
    write(view[:offset])
  File "/home/skydata/buy_it/env/lib/python3.8/site-packages/amqp/transport.py", line 305, in write
    self._write(s)
ConnectionResetError: [Errno 104] Connection reset by peer
[2021-04-25 17:33:16,789: ERROR/MainProcess] consumer: Cannot connect to amqp://guest:**@127.0.0.1:5672//: [Errno 111] Connection refused.
Trying again in 2.00 seconds... (1/100)


worker: Warm shutdown (MainProcess)
 
 -------------- celery@skydata-Latitude-E5430-non-vPro v4.4.7 (cliffs)
--- ***** ----- 
-- ******* ---- Linux-5.4.0-70-generic-x86_64-with-glibc2.29 2021-04-25 16:43:01
- *** --- * --- 
- ** ---------- [config]
- ** ---------- .> app:         buy_it:0x7f012d5a1d90
- ** ---------- .> transport:   amqp://guest:**@localhost:5672//
- ** ---------- .> results:     disabled://
- *** --- * --- .> concurrency: 4 (prefork)
-- ******* ---- .> task events: OFF (enable -E to monitor tasks in this worker)
--- ***** ----- 
 -------------- [queues]
                .> celery           exchange=celery(direct) key=celery
                

[tasks]
  . orders.tasks.order_created

[2021-04-26 15:32:30,321: INFO/MainProcess] Connected to amqp://guest:**@127.0.0.1:5672//
[2021-04-26 15:32:30,335: INFO/MainProcess] mingle: searching for neighbors
[2021-04-26 15:32:31,407: INFO/MainProcess] mingle: all alone
[2021-04-26 15:32:31,457: WARNING/MainProcess] /home/skydata/buy_it/env/lib/python3.8/site-packages/celery/fixups/django.py:205: UserWarning: Using settings.DEBUG leads to a memory
            leak, never use this setting in production environments!
  warnings.warn('''Using settings.DEBUG leads to a memory
[2021-04-26 15:32:31,457: INFO/MainProcess] celery@skydata-Latitude-E5430-non-vPro ready.
[2021-04-26 16:45:30,472: INFO/MainProcess] Connected to amqp://guest:**@127.0.0.1:5672//
[2021-04-26 16:45:30,487: INFO/MainProcess] mingle: searching for neighbors
[2021-04-26 16:45:31,559: INFO/MainProcess] mingle: all alone
[2021-04-26 16:45:31,602: WARNING/MainProcess] /home/skydata/buy_it/env/lib/python3.8/site-packages/celery/fixups/django.py:205: UserWarning: Using settings.DEBUG leads to a memory
            leak, never use this setting in production environments!
  warnings.warn('''Using settings.DEBUG leads to a memory
[2021-04-26 16:45:31,602: INFO/MainProcess] celery@skydata-Latitude-E5430-non-vPro ready.
[2021-04-27 17:15:22,419: INFO/MainProcess] Connected to amqp://guest:**@127.0.0.1:5672//
[2021-04-27 17:15:22,433: INFO/MainProcess] mingle: searching for neighbors
[2021-04-27 17:15:23,512: INFO/MainProcess] mingle: all alone
[2021-04-27 17:15:23,556: WARNING/MainProcess] /home/skydata/buy_it/env/lib/python3.8/site-packages/celery/fixups/django.py:205: UserWarning: Using settings.DEBUG leads to a memory
            leak, never use this setting in production environments!
  warnings.warn('''Using settings.DEBUG leads to a memory
[2021-04-27 17:15:23,556: INFO/MainProcess] celery@skydata-Latitude-E5430-non-vPro ready.
[2021-04-28 22:58:24,570: INFO/MainProcess] Connected to amqp://guest:**@127.0.0.1:5672//
[2021-04-28 22:58:24,582: INFO/MainProcess] mingle: searching for neighbors
[2021-04-28 22:58:25,658: INFO/MainProcess] mingle: all alone
[2021-04-28 22:58:25,740: WARNING/MainProcess] /home/skydata/buy_it/env/lib/python3.8/site-packages/celery/fixups/django.py:205: UserWarning: Using settings.DEBUG leads to a memory
            leak, never use this setting in production environments!
  warnings.warn('''Using settings.DEBUG leads to a memory
[2021-04-28 22:58:25,740: INFO/MainProcess] celery@skydata-Latitude-E5430-non-vPro ready.

worker: Warm shutdown (MainProcess)
 
 -------------- celery@skydata-Latitude-E5430-non-vPro v4.4.7 (cliffs)
--- ***** ----- 
-- ******* ---- Linux-5.4.0-70-generic-x86_64-with-glibc2.29 2021-04-28 22:58:23
- *** --- * --- 
- ** ---------- [config]
- ** ---------- .> app:         buy_it:0x7f3db02b2d90
- ** ---------- .> transport:   amqp://guest:**@localhost:5672//
- ** ---------- .> results:     disabled://
- *** --- * --- .> concurrency: 4 (prefork)
-- ******* ---- .> task events: OFF (enable -E to monitor tasks in this worker)
--- ***** ----- 
 -------------- [queues]
                .> celery           exchange=celery(direct) key=celery
                

[tasks]
  . orders.tasks.order_created

[2021-04-29 09:30:38,664: INFO/MainProcess] Connected to amqp://guest:**@127.0.0.1:5672//
[2021-04-29 09:30:38,674: INFO/MainProcess] mingle: searching for neighbors
[2021-04-29 09:30:39,737: INFO/MainProcess] mingle: all alone
[2021-04-29 09:30:39,775: WARNING/MainProcess] /home/skydata/buy_it/env/lib/python3.8/site-packages/celery/fixups/django.py:205: UserWarning: Using settings.DEBUG leads to a memory
            leak, never use this setting in production environments!
  warnings.warn('''Using settings.DEBUG leads to a memory
[2021-04-29 09:30:39,775: INFO/MainProcess] celery@skydata-Latitude-E5430-non-vPro ready.

worker: Warm shutdown (MainProcess)
 
 -------------- celery@skydata-Latitude-E5430-non-vPro v4.4.7 (cliffs)
--- ***** ----- 
-- ******* ---- Linux-5.4.0-70-generic-x86_64-with-glibc2.29 2021-04-29 09:30:38
- *** --- * --- 
- ** ---------- [config]
- ** ---------- .> app:         buy_it:0x7f0017b91dc0
- ** ---------- .> transport:   amqp://guest:**@localhost:5672//
- ** ---------- .> results:     disabled://
- *** --- * --- .> concurrency: 4 (prefork)
-- ******* ---- .> task events: OFF (enable -E to monitor tasks in this worker)
--- ***** ----- 
 -------------- [queues]
                .> celery           exchange=celery(direct) key=celery
                

[tasks]
  . orders.tasks.order_created

[2021-04-29 16:18:45,925: ERROR/MainProcess] consumer: Cannot connect to amqp://guest:**@127.0.0.1:5672//: [Errno 111] Connection refused.
Trying again in 2.00 seconds... (1/100)

[2021-04-29 16:18:47,942: INFO/MainProcess] Connected to amqp://guest:**@127.0.0.1:5672//
[2021-04-29 16:18:47,956: INFO/MainProcess] mingle: searching for neighbors
[2021-04-29 16:18:49,018: INFO/MainProcess] mingle: all alone
[2021-04-29 16:18:49,056: WARNING/MainProcess] /home/skydata/buy_it/env/lib/python3.8/site-packages/celery/fixups/django.py:205: UserWarning: Using settings.DEBUG leads to a memory
            leak, never use this setting in production environments!
  warnings.warn('''Using settings.DEBUG leads to a memory
[2021-04-29 16:18:49,056: INFO/MainProcess] celery@skydata-Latitude-E5430-non-vPro ready.
[2021-04-29 19:20:57,203: WARNING/MainProcess] consumer: Connection to broker lost. Trying to re-establish the connection...
Traceback (most recent call last):
  File "/home/skydata/buy_it/env/lib/python3.8/site-packages/celery/worker/consumer/consumer.py", line 318, in start
    blueprint.start(self)
  File "/home/skydata/buy_it/env/lib/python3.8/site-packages/celery/bootsteps.py", line 119, in start
    step.start(parent)
  File "/home/skydata/buy_it/env/lib/python3.8/site-packages/celery/worker/consumer/consumer.py", line 599, in start
    c.loop(*c.loop_args())
  File "/home/skydata/buy_it/env/lib/python3.8/site-packages/celery/worker/loops.py", line 83, in asynloop
    next(loop)
  File "/home/skydata/buy_it/env/lib/python3.8/site-packages/kombu/asynchronous/hub.py", line 364, in create_loop
    cb(*cbargs)
  File "/home/skydata/buy_it/env/lib/python3.8/site-packages/kombu/transport/base.py", line 238, in on_readable
    reader(loop)
  File "/home/skydata/buy_it/env/lib/python3.8/site-packages/kombu/transport/base.py", line 220, in _read
    drain_events(timeout=0)
  File "/home/skydata/buy_it/env/lib/python3.8/site-packages/amqp/connection.py", line 508, in drain_events
    while not self.blocking_read(timeout):
  File "/home/skydata/buy_it/env/lib/python3.8/site-packages/amqp/connection.py", line 514, in blocking_read
    return self.on_inbound_frame(frame)
  File "/home/skydata/buy_it/env/lib/python3.8/site-packages/amqp/method_framing.py", line 55, in on_frame
    callback(channel, method_sig, buf, None)
  File "/home/skydata/buy_it/env/lib/python3.8/site-packages/amqp/connection.py", line 520, in on_inbound_method
    return self.channels[channel_id].dispatch_method(
  File "/home/skydata/buy_it/env/lib/python3.8/site-packages/amqp/abstract_channel.py", line 145, in dispatch_method
    listener(*args)
  File "/home/skydata/buy_it/env/lib/python3.8/site-packages/amqp/connection.py", line 649, in _on_close
    self._x_close_ok()
  File "/home/skydata/buy_it/env/lib/python3.8/site-packages/amqp/connection.py", line 664, in _x_close_ok
    self.send_method(spec.Connection.CloseOk, callback=self._on_close_ok)
  File "/home/skydata/buy_it/env/lib/python3.8/site-packages/amqp/abstract_channel.py", line 59, in send_method
    conn.frame_writer(1, self.channel_id, sig, args, content)
  File "/home/skydata/buy_it/env/lib/python3.8/site-packages/amqp/method_framing.py", line 189, in write_frame
    write(view[:offset])
  File "/home/skydata/buy_it/env/lib/python3.8/site-packages/amqp/transport.py", line 305, in write
    self._write(s)
ConnectionResetError: [Errno 104] Connection reset by peer
[2021-04-29 19:20:58,030: ERROR/MainProcess] consumer: Cannot connect to amqp://guest:**@127.0.0.1:5672//: [Errno 111] Connection refused.
Trying again in 2.00 seconds... (1/100)


worker: Warm shutdown (MainProcess)
 
 -------------- celery@skydata-Latitude-E5430-non-vPro v4.4.7 (cliffs)
--- ***** ----- 
-- ******* ---- Linux-5.4.0-70-generic-x86_64-with-glibc2.29 2021-04-29 16:18:45
- *** --- * --- 
- ** ---------- [config]
- ** ---------- .> app:         buy_it:0x7f41d7d59d90
- ** ---------- .> transport:   amqp://guest:**@localhost:5672//
- ** ---------- .> results:     disabled://
- *** --- * --- .> concurrency: 4 (prefork)
-- ******* ---- .> task events: OFF (enable -E to monitor tasks in this worker)
--- ***** ----- 
 -------------- [queues]
                .> celery           exchange=celery(direct) key=celery
                

[tasks]
  . orders.tasks.order_created

[2021-04-29 22:36:45,727: ERROR/MainProcess] consumer: Cannot connect to amqp://guest:**@127.0.0.1:5672//: [Errno 111] Connection refused.
Trying again in 2.00 seconds... (1/100)

[2021-04-29 22:36:47,751: INFO/MainProcess] Connected to amqp://guest:**@127.0.0.1:5672//
[2021-04-29 22:36:47,766: INFO/MainProcess] mingle: searching for neighbors
[2021-04-29 22:36:48,836: INFO/MainProcess] mingle: all alone
[2021-04-29 22:36:48,870: WARNING/MainProcess] /home/skydata/buy_it/env/lib/python3.8/site-packages/celery/fixups/django.py:205: UserWarning: Using settings.DEBUG leads to a memory
            leak, never use this setting in production environments!
  warnings.warn('''Using settings.DEBUG leads to a memory
[2021-04-29 22:36:48,870: INFO/MainProcess] celery@skydata-Latitude-E5430-non-vPro ready.
[2021-04-30 21:55:25,311: ERROR/MainProcess] consumer: Cannot connect to amqp://guest:**@127.0.0.1:5672//: [Errno 111] Connection refused.
Trying again in 2.00 seconds... (1/100)

[2021-04-30 21:55:27,337: INFO/MainProcess] Connected to amqp://guest:**@127.0.0.1:5672//
[2021-04-30 21:55:27,347: INFO/MainProcess] mingle: searching for neighbors
[2021-04-30 21:55:28,414: INFO/MainProcess] mingle: all alone
[2021-04-30 21:55:28,460: WARNING/MainProcess] /home/skydata/buy_it/env/lib/python3.8/site-packages/celery/fixups/django.py:205: UserWarning: Using settings.DEBUG leads to a memory
            leak, never use this setting in production environments!
  warnings.warn('''Using settings.DEBUG leads to a memory
[2021-04-30 21:55:28,460: INFO/MainProcess] celery@skydata-Latitude-E5430-non-vPro ready.
[2021-05-01 11:47:03,735: INFO/MainProcess] Connected to amqp://guest:**@127.0.0.1:5672//
[2021-05-01 11:47:03,750: INFO/MainProcess] mingle: searching for neighbors
[2021-05-01 11:47:04,825: INFO/MainProcess] mingle: all alone
[2021-05-01 11:47:04,890: WARNING/MainProcess] /home/skydata/buy_it/env/lib/python3.8/site-packages/celery/fixups/django.py:205: UserWarning: Using settings.DEBUG leads to a memory
            leak, never use this setting in production environments!
  warnings.warn('''Using settings.DEBUG leads to a memory
[2021-05-01 11:47:04,891: INFO/MainProcess] celery@skydata-Latitude-E5430-non-vPro ready.
[2021-05-03 11:19:00,338: INFO/MainProcess] Received task: orders.tasks.order_created[d60f28e0-708a-498a-a9b9-15b93b4ffda5]  
[2021-05-03 11:19:40,501: ERROR/ForkPoolWorker-2] Task orders.tasks.order_created[d60f28e0-708a-498a-a9b9-15b93b4ffda5] raised unexpected: SMTPAuthenticationError(534, b'5.7.14 <https://accounts.google.com/signin/continue?sarp=1&scc=1&plt=AKgnsbv\n5.7.14 jBwNBMKOgWAB5sRDAUr5s4V26MXDmfaWYkm_TLIQBI-RHHgVcvwGwPHe9Ix0yPHhNsPd8\n5.7.14 nwJXxN_DVPYjg8d4kJd7BWGqsWFxRozNSbQ45N47j-VGpacOpJtTtJ3HQyjAFiun>\n5.7.14 Please log in via your web browser and then try again.\n5.7.14  Learn more at\n5.7.14  https://support.google.com/mail/answer/78754 p10sm12651798wre.84 - gsmtp')
Traceback (most recent call last):
  File "/home/skydata/buy_it/env/lib/python3.8/site-packages/celery/app/trace.py", line 412, in trace_task
    R = retval = fun(*args, **kwargs)
  File "/home/skydata/buy_it/env/lib/python3.8/site-packages/celery/app/trace.py", line 704, in __protected_call__
    return self.run(*args, **kwargs)
  File "/home/skydata/buy_it/src/orders/tasks.py", line 13, in order_created
    mail_sent = send_mail(subject, message, 'admin@buy_it.com', {order.email})
  File "/home/skydata/buy_it/env/lib/python3.8/site-packages/django/core/mail/__init__.py", line 61, in send_mail
    return mail.send()
  File "/home/skydata/buy_it/env/lib/python3.8/site-packages/django/core/mail/message.py", line 284, in send
    return self.get_connection(fail_silently).send_messages([self])
  File "/home/skydata/buy_it/env/lib/python3.8/site-packages/django/core/mail/backends/smtp.py", line 102, in send_messages
    new_conn_created = self.open()
  File "/home/skydata/buy_it/env/lib/python3.8/site-packages/django/core/mail/backends/smtp.py", line 69, in open
    self.connection.login(self.username, self.password)
  File "/usr/lib/python3.8/smtplib.py", line 734, in login
    raise last_exception
  File "/usr/lib/python3.8/smtplib.py", line 723, in login
    (code, resp) = self.auth(
  File "/usr/lib/python3.8/smtplib.py", line 646, in auth
    raise SMTPAuthenticationError(code, resp)
smtplib.SMTPAuthenticationError: (534, b'5.7.14 <https://accounts.google.com/signin/continue?sarp=1&scc=1&plt=AKgnsbv\n5.7.14 jBwNBMKOgWAB5sRDAUr5s4V26MXDmfaWYkm_TLIQBI-RHHgVcvwGwPHe9Ix0yPHhNsPd8\n5.7.14 nwJXxN_DVPYjg8d4kJd7BWGqsWFxRozNSbQ45N47j-VGpacOpJtTtJ3HQyjAFiun>\n5.7.14 Please log in via your web browser and then try again.\n5.7.14  Learn more at\n5.7.14  https://support.google.com/mail/answer/78754 p10sm12651798wre.84 - gsmtp')
[2021-05-03 18:09:25,489: INFO/MainProcess] Connected to amqp://guest:**@127.0.0.1:5672//
[2021-05-03 18:09:25,499: INFO/MainProcess] mingle: searching for neighbors
[2021-05-03 18:09:26,579: INFO/MainProcess] mingle: all alone
[2021-05-03 18:09:26,605: WARNING/MainProcess] /home/skydata/buy_it/env/lib/python3.8/site-packages/celery/fixups/django.py:205: UserWarning: Using settings.DEBUG leads to a memory
            leak, never use this setting in production environments!
  warnings.warn('''Using settings.DEBUG leads to a memory
[2021-05-03 18:09:26,605: INFO/MainProcess] celery@skydata-Latitude-E5430-non-vPro ready.
[2021-05-06 22:51:57,993: WARNING/MainProcess] consumer: Connection to broker lost. Trying to re-establish the connection...
Traceback (most recent call last):
  File "/home/skydata/buy_it/env/lib/python3.8/site-packages/celery/worker/consumer/consumer.py", line 318, in start
    blueprint.start(self)
  File "/home/skydata/buy_it/env/lib/python3.8/site-packages/celery/bootsteps.py", line 119, in start
    step.start(parent)
  File "/home/skydata/buy_it/env/lib/python3.8/site-packages/celery/worker/consumer/consumer.py", line 599, in start
    c.loop(*c.loop_args())
  File "/home/skydata/buy_it/env/lib/python3.8/site-packages/celery/worker/loops.py", line 83, in asynloop
    next(loop)
  File "/home/skydata/buy_it/env/lib/python3.8/site-packages/kombu/asynchronous/hub.py", line 364, in create_loop
    cb(*cbargs)
  File "/home/skydata/buy_it/env/lib/python3.8/site-packages/kombu/transport/base.py", line 238, in on_readable
    reader(loop)
  File "/home/skydata/buy_it/env/lib/python3.8/site-packages/kombu/transport/base.py", line 220, in _read
    drain_events(timeout=0)
  File "/home/skydata/buy_it/env/lib/python3.8/site-packages/amqp/connection.py", line 508, in drain_events
    while not self.blocking_read(timeout):
  File "/home/skydata/buy_it/env/lib/python3.8/site-packages/amqp/connection.py", line 514, in blocking_read
    return self.on_inbound_frame(frame)
  File "/home/skydata/buy_it/env/lib/python3.8/site-packages/amqp/method_framing.py", line 55, in on_frame
    callback(channel, method_sig, buf, None)
  File "/home/skydata/buy_it/env/lib/python3.8/site-packages/amqp/connection.py", line 520, in on_inbound_method
    return self.channels[channel_id].dispatch_method(
  File "/home/skydata/buy_it/env/lib/python3.8/site-packages/amqp/abstract_channel.py", line 145, in dispatch_method
    listener(*args)
  File "/home/skydata/buy_it/env/lib/python3.8/site-packages/amqp/connection.py", line 649, in _on_close
    self._x_close_ok()
  File "/home/skydata/buy_it/env/lib/python3.8/site-packages/amqp/connection.py", line 664, in _x_close_ok
    self.send_method(spec.Connection.CloseOk, callback=self._on_close_ok)
  File "/home/skydata/buy_it/env/lib/python3.8/site-packages/amqp/abstract_channel.py", line 59, in send_method
    conn.frame_writer(1, self.channel_id, sig, args, content)
  File "/home/skydata/buy_it/env/lib/python3.8/site-packages/amqp/method_framing.py", line 189, in write_frame
    write(view[:offset])
  File "/home/skydata/buy_it/env/lib/python3.8/site-packages/amqp/transport.py", line 305, in write
    self._write(s)
ConnectionResetError: [Errno 104] Connection reset by peer
[2021-05-06 22:51:58,775: ERROR/MainProcess] consumer: Cannot connect to amqp://guest:**@127.0.0.1:5672//: [Errno 111] Connection refused.
Trying again in 2.00 seconds... (1/100)

[2021-05-06 22:52:00,791: ERROR/MainProcess] consumer: Cannot connect to amqp://guest:**@127.0.0.1:5672//: [Errno 111] Connection refused.
Trying again in 4.00 seconds... (2/100)


worker: Warm shutdown (MainProcess)
 
 -------------- celery@skydata-Latitude-E5430-non-vPro v4.4.7 (cliffs)
--- ***** ----- 
-- ******* ---- Linux-5.4.0-70-generic-x86_64-with-glibc2.29 2021-05-03 18:09:25
- *** --- * --- 
- ** ---------- [config]
- ** ---------- .> app:         buy_it:0x7f1198e1d430
- ** ---------- .> transport:   amqp://guest:**@localhost:5672//
- ** ---------- .> results:     disabled://
- *** --- * --- .> concurrency: 4 (prefork)
-- ******* ---- .> task events: OFF (enable -E to monitor tasks in this worker)
--- ***** ----- 
 -------------- [queues]
                .> celery           exchange=celery(direct) key=celery
                

[tasks]
  . orders.tasks.order_created

[2021-05-06 22:54:44,386: INFO/MainProcess] Connected to amqp://guest:**@127.0.0.1:5672//
[2021-05-06 22:54:44,395: INFO/MainProcess] mingle: searching for neighbors
[2021-05-06 22:54:45,465: INFO/MainProcess] mingle: all alone
[2021-05-06 22:54:45,501: INFO/MainProcess] celery@skydata-Latitude-E5430-non-vPro ready.
[2021-05-07 20:10:10,930: INFO/MainProcess] Connected to amqp://guest:**@127.0.0.1:5672//
[2021-05-07 20:10:10,942: INFO/MainProcess] mingle: searching for neighbors
[2021-05-07 20:10:12,015: INFO/MainProcess] mingle: all alone
[2021-05-07 20:10:12,054: WARNING/MainProcess] /home/skydata/buy_it/env/lib/python3.8/site-packages/celery/fixups/django.py:205: UserWarning: Using settings.DEBUG leads to a memory
            leak, never use this setting in production environments!
  warnings.warn('''Using settings.DEBUG leads to a memory
[2021-05-07 20:10:12,054: INFO/MainProcess] celery@skydata-Latitude-E5430-non-vPro ready.

worker: Warm shutdown (MainProcess)
 
 -------------- celery@skydata-Latitude-E5430-non-vPro v4.4.7 (cliffs)
--- ***** ----- 
-- ******* ---- Linux-5.4.0-70-generic-x86_64-with-glibc2.29 2021-05-07 20:10:10
- *** --- * --- 
- ** ---------- [config]
- ** ---------- .> app:         buy_it:0x7fbf842484c0
- ** ---------- .> transport:   amqp://guest:**@localhost:5672//
- ** ---------- .> results:     disabled://
- *** --- * --- .> concurrency: 4 (prefork)
-- ******* ---- .> task events: OFF (enable -E to monitor tasks in this worker)
--- ***** ----- 
 -------------- [queues]
                .> celery           exchange=celery(direct) key=celery
                

[tasks]
  . orders.tasks.order_created

[2021-05-09 15:09:09,742: INFO/MainProcess] Connected to amqp://guest:**@127.0.0.1:5672//
[2021-05-09 15:09:09,752: INFO/MainProcess] mingle: searching for neighbors
[2021-05-09 15:09:10,865: INFO/MainProcess] mingle: all alone
[2021-05-09 15:09:10,894: WARNING/MainProcess] /home/skydata/buy_it/env/lib/python3.8/site-packages/celery/fixups/django.py:205: UserWarning: Using settings.DEBUG leads to a memory
            leak, never use this setting in production environments!
  warnings.warn('''Using settings.DEBUG leads to a memory
[2021-05-09 15:09:10,894: INFO/MainProcess] celery@skydata-Latitude-E5430-non-vPro ready.
[2021-05-16 12:05:39,962: INFO/MainProcess] Connected to amqp://guest:**@127.0.0.1:5672//
[2021-05-16 12:05:39,972: INFO/MainProcess] mingle: searching for neighbors
[2021-05-16 12:05:41,038: INFO/MainProcess] mingle: all alone
[2021-05-16 12:05:41,073: WARNING/MainProcess] /home/skydata/buy_it/env/lib/python3.8/site-packages/celery/fixups/django.py:205: UserWarning: Using settings.DEBUG leads to a memory
            leak, never use this setting in production environments!
  warnings.warn('''Using settings.DEBUG leads to a memory
[2021-05-16 12:05:41,074: INFO/MainProcess] celery@skydata-Latitude-E5430-non-vPro ready.
