[2021-04-25 16:43:01,637: ERROR/MainProcess] consumer: Cannot connect to amqp://guest:**@127.0.0.1:5672//: [Errno 111] Connection refused.
Trying again in 2.00 seconds... (1/100)

[2021-04-25 16:43:03,655: INFO/MainProcess] Connected to amqp://guest:**@127.0.0.1:5672//
[2021-04-25 16:43:03,668: INFO/MainProcess] mingle: searching for neighbors
[2021-04-25 16:43:04,738: INFO/MainProcess] mingle: all alone
[2021-04-25 16:43:04,773: WARNING/MainProcess] /home/skydata/buy_it/env/lib/python3.8/site-packages/celery/fixups/django.py:205: UserWarning: Using settings.DEBUG leads to a memory
            leak, never use this setting in production environments!
  warnings.warn('''Using settings.DEBUG leads to a memory
[2021-04-25 16:43:04,773: INFO/MainProcess] celery@skydata-Latitude-E5430-non-vPro ready.
[2021-04-25 17:33:16,110: WARNING/MainProcess] consumer: Connection to broker lost. Trying to re-establish the connection...
Traceback (most recent call last):
  File "/home/skydata/buy_it/env/lib/python3.8/site-packages/celery/worker/consumer/consumer.py", line 318, in start
    blueprint.start(self)
  File "/home/skydata/buy_it/env/lib/python3.8/site-packages/celery/bootsteps.py", line 119, in start
    step.start(parent)
  File "/home/skydata/buy_it/env/lib/python3.8/site-packages/celery/worker/consumer/consumer.py", line 599, in start
    c.loop(*c.loop_args())
  File "/home/skydata/buy_it/env/lib/python3.8/site-packages/celery/worker/loops.py", line 83, in asynloop
    next(loop)
  File "/home/skydata/buy_it/env/lib/python3.8/site-packages/kombu/asynchronous/hub.py", line 364, in create_loop
    cb(*cbargs)
  File "/home/skydata/buy_it/env/lib/python3.8/site-packages/kombu/transport/base.py", line 238, in on_readable
    reader(loop)
  File "/home/skydata/buy_it/env/lib/python3.8/site-packages/kombu/transport/base.py", line 220, in _read
    drain_events(timeout=0)
  File "/home/skydata/buy_it/env/lib/python3.8/site-packages/amqp/connection.py", line 508, in drain_events
    while not self.blocking_read(timeout):
  File "/home/skydata/buy_it/env/lib/python3.8/site-packages/amqp/connection.py", line 514, in blocking_read
    return self.on_inbound_frame(frame)
  File "/home/skydata/buy_it/env/lib/python3.8/site-packages/amqp/method_framing.py", line 55, in on_frame
    callback(channel, method_sig, buf, None)
  File "/home/skydata/buy_it/env/lib/python3.8/site-packages/amqp/connection.py", line 520, in on_inbound_method
    return self.channels[channel_id].dispatch_method(
  File "/home/skydata/buy_it/env/lib/python3.8/site-packages/amqp/abstract_channel.py", line 145, in dispatch_method
    listener(*args)
  File "/home/skydata/buy_it/env/lib/python3.8/site-packages/amqp/connection.py", line 649, in _on_close
    self._x_close_ok()
  File "/home/skydata/buy_it/env/lib/python3.8/site-packages/amqp/connection.py", line 664, in _x_close_ok
    self.send_method(spec.Connection.CloseOk, callback=self._on_close_ok)
  File "/home/skydata/buy_it/env/lib/python3.8/site-packages/amqp/abstract_channel.py", line 59, in send_method
    conn.frame_writer(1, self.channel_id, sig, args, content)
  File "/home/skydata/buy_it/env/lib/python3.8/site-packages/amqp/method_framing.py", line 189, in write_frame
    write(view[:offset])
  File "/home/skydata/buy_it/env/lib/python3.8/site-packages/amqp/transport.py", line 305, in write
    self._write(s)
ConnectionResetError: [Errno 104] Connection reset by peer
[2021-04-25 17:33:16,789: ERROR/MainProcess] consumer: Cannot connect to amqp://guest:**@127.0.0.1:5672//: [Errno 111] Connection refused.
Trying again in 2.00 seconds... (1/100)


worker: Warm shutdown (MainProcess)
 
 -------------- celery@skydata-Latitude-E5430-non-vPro v4.4.7 (cliffs)
--- ***** ----- 
-- ******* ---- Linux-5.4.0-70-generic-x86_64-with-glibc2.29 2021-04-25 16:43:01
- *** --- * --- 
- ** ---------- [config]
- ** ---------- .> app:         buy_it:0x7f012d5a1d90
- ** ---------- .> transport:   amqp://guest:**@localhost:5672//
- ** ---------- .> results:     disabled://
- *** --- * --- .> concurrency: 4 (prefork)
-- ******* ---- .> task events: OFF (enable -E to monitor tasks in this worker)
--- ***** ----- 
 -------------- [queues]
                .> celery           exchange=celery(direct) key=celery
                

[tasks]
  . orders.tasks.order_created

[2021-04-26 15:32:30,321: INFO/MainProcess] Connected to amqp://guest:**@127.0.0.1:5672//
[2021-04-26 15:32:30,335: INFO/MainProcess] mingle: searching for neighbors
[2021-04-26 15:32:31,407: INFO/MainProcess] mingle: all alone
[2021-04-26 15:32:31,457: WARNING/MainProcess] /home/skydata/buy_it/env/lib/python3.8/site-packages/celery/fixups/django.py:205: UserWarning: Using settings.DEBUG leads to a memory
            leak, never use this setting in production environments!
  warnings.warn('''Using settings.DEBUG leads to a memory
[2021-04-26 15:32:31,457: INFO/MainProcess] celery@skydata-Latitude-E5430-non-vPro ready.
[2021-04-26 16:45:30,472: INFO/MainProcess] Connected to amqp://guest:**@127.0.0.1:5672//
[2021-04-26 16:45:30,487: INFO/MainProcess] mingle: searching for neighbors
[2021-04-26 16:45:31,559: INFO/MainProcess] mingle: all alone
[2021-04-26 16:45:31,602: WARNING/MainProcess] /home/skydata/buy_it/env/lib/python3.8/site-packages/celery/fixups/django.py:205: UserWarning: Using settings.DEBUG leads to a memory
            leak, never use this setting in production environments!
  warnings.warn('''Using settings.DEBUG leads to a memory
[2021-04-26 16:45:31,602: INFO/MainProcess] celery@skydata-Latitude-E5430-non-vPro ready.
[2021-04-27 17:15:22,419: INFO/MainProcess] Connected to amqp://guest:**@127.0.0.1:5672//
[2021-04-27 17:15:22,433: INFO/MainProcess] mingle: searching for neighbors
[2021-04-27 17:15:23,512: INFO/MainProcess] mingle: all alone
[2021-04-27 17:15:23,556: WARNING/MainProcess] /home/skydata/buy_it/env/lib/python3.8/site-packages/celery/fixups/django.py:205: UserWarning: Using settings.DEBUG leads to a memory
            leak, never use this setting in production environments!
  warnings.warn('''Using settings.DEBUG leads to a memory
[2021-04-27 17:15:23,556: INFO/MainProcess] celery@skydata-Latitude-E5430-non-vPro ready.
[2021-04-28 22:58:24,570: INFO/MainProcess] Connected to amqp://guest:**@127.0.0.1:5672//
[2021-04-28 22:58:24,582: INFO/MainProcess] mingle: searching for neighbors
[2021-04-28 22:58:25,658: INFO/MainProcess] mingle: all alone
[2021-04-28 22:58:25,740: WARNING/MainProcess] /home/skydata/buy_it/env/lib/python3.8/site-packages/celery/fixups/django.py:205: UserWarning: Using settings.DEBUG leads to a memory
            leak, never use this setting in production environments!
  warnings.warn('''Using settings.DEBUG leads to a memory
[2021-04-28 22:58:25,740: INFO/MainProcess] celery@skydata-Latitude-E5430-non-vPro ready.

worker: Warm shutdown (MainProcess)
 
 -------------- celery@skydata-Latitude-E5430-non-vPro v4.4.7 (cliffs)
--- ***** ----- 
-- ******* ---- Linux-5.4.0-70-generic-x86_64-with-glibc2.29 2021-04-28 22:58:23
- *** --- * --- 
- ** ---------- [config]
- ** ---------- .> app:         buy_it:0x7f3db02b2d90
- ** ---------- .> transport:   amqp://guest:**@localhost:5672//
- ** ---------- .> results:     disabled://
- *** --- * --- .> concurrency: 4 (prefork)
-- ******* ---- .> task events: OFF (enable -E to monitor tasks in this worker)
--- ***** ----- 
 -------------- [queues]
                .> celery           exchange=celery(direct) key=celery
                

[tasks]
  . orders.tasks.order_created

[2021-04-29 09:30:38,664: INFO/MainProcess] Connected to amqp://guest:**@127.0.0.1:5672//
[2021-04-29 09:30:38,674: INFO/MainProcess] mingle: searching for neighbors
[2021-04-29 09:30:39,737: INFO/MainProcess] mingle: all alone
[2021-04-29 09:30:39,775: WARNING/MainProcess] /home/skydata/buy_it/env/lib/python3.8/site-packages/celery/fixups/django.py:205: UserWarning: Using settings.DEBUG leads to a memory
            leak, never use this setting in production environments!
  warnings.warn('''Using settings.DEBUG leads to a memory
[2021-04-29 09:30:39,775: INFO/MainProcess] celery@skydata-Latitude-E5430-non-vPro ready.

worker: Warm shutdown (MainProcess)
 
 -------------- celery@skydata-Latitude-E5430-non-vPro v4.4.7 (cliffs)
--- ***** ----- 
-- ******* ---- Linux-5.4.0-70-generic-x86_64-with-glibc2.29 2021-04-29 09:30:38
- *** --- * --- 
- ** ---------- [config]
- ** ---------- .> app:         buy_it:0x7f0017b91dc0
- ** ---------- .> transport:   amqp://guest:**@localhost:5672//
- ** ---------- .> results:     disabled://
- *** --- * --- .> concurrency: 4 (prefork)
-- ******* ---- .> task events: OFF (enable -E to monitor tasks in this worker)
--- ***** ----- 
 -------------- [queues]
                .> celery           exchange=celery(direct) key=celery
                

[tasks]
  . orders.tasks.order_created

[2021-04-29 16:18:45,925: ERROR/MainProcess] consumer: Cannot connect to amqp://guest:**@127.0.0.1:5672//: [Errno 111] Connection refused.
Trying again in 2.00 seconds... (1/100)

[2021-04-29 16:18:47,942: INFO/MainProcess] Connected to amqp://guest:**@127.0.0.1:5672//
[2021-04-29 16:18:47,956: INFO/MainProcess] mingle: searching for neighbors
[2021-04-29 16:18:49,018: INFO/MainProcess] mingle: all alone
[2021-04-29 16:18:49,056: WARNING/MainProcess] /home/skydata/buy_it/env/lib/python3.8/site-packages/celery/fixups/django.py:205: UserWarning: Using settings.DEBUG leads to a memory
            leak, never use this setting in production environments!
  warnings.warn('''Using settings.DEBUG leads to a memory
[2021-04-29 16:18:49,056: INFO/MainProcess] celery@skydata-Latitude-E5430-non-vPro ready.
[2021-04-29 19:20:57,203: WARNING/MainProcess] consumer: Connection to broker lost. Trying to re-establish the connection...
Traceback (most recent call last):
  File "/home/skydata/buy_it/env/lib/python3.8/site-packages/celery/worker/consumer/consumer.py", line 318, in start
    blueprint.start(self)
  File "/home/skydata/buy_it/env/lib/python3.8/site-packages/celery/bootsteps.py", line 119, in start
    step.start(parent)
  File "/home/skydata/buy_it/env/lib/python3.8/site-packages/celery/worker/consumer/consumer.py", line 599, in start
    c.loop(*c.loop_args())
  File "/home/skydata/buy_it/env/lib/python3.8/site-packages/celery/worker/loops.py", line 83, in asynloop
    next(loop)
  File "/home/skydata/buy_it/env/lib/python3.8/site-packages/kombu/asynchronous/hub.py", line 364, in create_loop
    cb(*cbargs)
  File "/home/skydata/buy_it/env/lib/python3.8/site-packages/kombu/transport/base.py", line 238, in on_readable
    reader(loop)
  File "/home/skydata/buy_it/env/lib/python3.8/site-packages/kombu/transport/base.py", line 220, in _read
    drain_events(timeout=0)
  File "/home/skydata/buy_it/env/lib/python3.8/site-packages/amqp/connection.py", line 508, in drain_events
    while not self.blocking_read(timeout):
  File "/home/skydata/buy_it/env/lib/python3.8/site-packages/amqp/connection.py", line 514, in blocking_read
    return self.on_inbound_frame(frame)
  File "/home/skydata/buy_it/env/lib/python3.8/site-packages/amqp/method_framing.py", line 55, in on_frame
    callback(channel, method_sig, buf, None)
  File "/home/skydata/buy_it/env/lib/python3.8/site-packages/amqp/connection.py", line 520, in on_inbound_method
    return self.channels[channel_id].dispatch_method(
  File "/home/skydata/buy_it/env/lib/python3.8/site-packages/amqp/abstract_channel.py", line 145, in dispatch_method
    listener(*args)
  File "/home/skydata/buy_it/env/lib/python3.8/site-packages/amqp/connection.py", line 649, in _on_close
    self._x_close_ok()
  File "/home/skydata/buy_it/env/lib/python3.8/site-packages/amqp/connection.py", line 664, in _x_close_ok
    self.send_method(spec.Connection.CloseOk, callback=self._on_close_ok)
  File "/home/skydata/buy_it/env/lib/python3.8/site-packages/amqp/abstract_channel.py", line 59, in send_method
    conn.frame_writer(1, self.channel_id, sig, args, content)
  File "/home/skydata/buy_it/env/lib/python3.8/site-packages/amqp/method_framing.py", line 189, in write_frame
    write(view[:offset])
  File "/home/skydata/buy_it/env/lib/python3.8/site-packages/amqp/transport.py", line 305, in write
    self._write(s)
ConnectionResetError: [Errno 104] Connection reset by peer
[2021-04-29 19:20:58,030: ERROR/MainProcess] consumer: Cannot connect to amqp://guest:**@127.0.0.1:5672//: [Errno 111] Connection refused.
Trying again in 2.00 seconds... (1/100)


worker: Warm shutdown (MainProcess)
 
 -------------- celery@skydata-Latitude-E5430-non-vPro v4.4.7 (cliffs)
--- ***** ----- 
-- ******* ---- Linux-5.4.0-70-generic-x86_64-with-glibc2.29 2021-04-29 16:18:45
- *** --- * --- 
- ** ---------- [config]
- ** ---------- .> app:         buy_it:0x7f41d7d59d90
- ** ---------- .> transport:   amqp://guest:**@localhost:5672//
- ** ---------- .> results:     disabled://
- *** --- * --- .> concurrency: 4 (prefork)
-- ******* ---- .> task events: OFF (enable -E to monitor tasks in this worker)
--- ***** ----- 
 -------------- [queues]
                .> celery           exchange=celery(direct) key=celery
                

[tasks]
  . orders.tasks.order_created

[2021-04-29 22:36:45,727: ERROR/MainProcess] consumer: Cannot connect to amqp://guest:**@127.0.0.1:5672//: [Errno 111] Connection refused.
Trying again in 2.00 seconds... (1/100)

[2021-04-29 22:36:47,751: INFO/MainProcess] Connected to amqp://guest:**@127.0.0.1:5672//
[2021-04-29 22:36:47,766: INFO/MainProcess] mingle: searching for neighbors
[2021-04-29 22:36:48,836: INFO/MainProcess] mingle: all alone
[2021-04-29 22:36:48,870: WARNING/MainProcess] /home/skydata/buy_it/env/lib/python3.8/site-packages/celery/fixups/django.py:205: UserWarning: Using settings.DEBUG leads to a memory
            leak, never use this setting in production environments!
  warnings.warn('''Using settings.DEBUG leads to a memory
[2021-04-29 22:36:48,870: INFO/MainProcess] celery@skydata-Latitude-E5430-non-vPro ready.
[2021-04-30 21:55:25,311: ERROR/MainProcess] consumer: Cannot connect to amqp://guest:**@127.0.0.1:5672//: [Errno 111] Connection refused.
Trying again in 2.00 seconds... (1/100)

[2021-04-30 21:55:27,337: INFO/MainProcess] Connected to amqp://guest:**@127.0.0.1:5672//
[2021-04-30 21:55:27,347: INFO/MainProcess] mingle: searching for neighbors
[2021-04-30 21:55:28,414: INFO/MainProcess] mingle: all alone
[2021-04-30 21:55:28,460: WARNING/MainProcess] /home/skydata/buy_it/env/lib/python3.8/site-packages/celery/fixups/django.py:205: UserWarning: Using settings.DEBUG leads to a memory
            leak, never use this setting in production environments!
  warnings.warn('''Using settings.DEBUG leads to a memory
[2021-04-30 21:55:28,460: INFO/MainProcess] celery@skydata-Latitude-E5430-non-vPro ready.
[2021-05-01 11:47:03,735: INFO/MainProcess] Connected to amqp://guest:**@127.0.0.1:5672//
[2021-05-01 11:47:03,750: INFO/MainProcess] mingle: searching for neighbors
[2021-05-01 11:47:04,825: INFO/MainProcess] mingle: all alone
[2021-05-01 11:47:04,890: WARNING/MainProcess] /home/skydata/buy_it/env/lib/python3.8/site-packages/celery/fixups/django.py:205: UserWarning: Using settings.DEBUG leads to a memory
            leak, never use this setting in production environments!
  warnings.warn('''Using settings.DEBUG leads to a memory
[2021-05-01 11:47:04,891: INFO/MainProcess] celery@skydata-Latitude-E5430-non-vPro ready.
[2021-05-03 11:19:00,338: INFO/MainProcess] Received task: orders.tasks.order_created[d60f28e0-708a-498a-a9b9-15b93b4ffda5]  
[2021-05-03 11:19:40,501: ERROR/ForkPoolWorker-2] Task orders.tasks.order_created[d60f28e0-708a-498a-a9b9-15b93b4ffda5] raised unexpected: SMTPAuthenticationError(534, b'5.7.14 <https://accounts.google.com/signin/continue?sarp=1&scc=1&plt=AKgnsbv\n5.7.14 jBwNBMKOgWAB5sRDAUr5s4V26MXDmfaWYkm_TLIQBI-RHHgVcvwGwPHe9Ix0yPHhNsPd8\n5.7.14 nwJXxN_DVPYjg8d4kJd7BWGqsWFxRozNSbQ45N47j-VGpacOpJtTtJ3HQyjAFiun>\n5.7.14 Please log in via your web browser and then try again.\n5.7.14  Learn more at\n5.7.14  https://support.google.com/mail/answer/78754 p10sm12651798wre.84 - gsmtp')
Traceback (most recent call last):
  File "/home/skydata/buy_it/env/lib/python3.8/site-packages/celery/app/trace.py", line 412, in trace_task
    R = retval = fun(*args, **kwargs)
  File "/home/skydata/buy_it/env/lib/python3.8/site-packages/celery/app/trace.py", line 704, in __protected_call__
    return self.run(*args, **kwargs)
  File "/home/skydata/buy_it/src/orders/tasks.py", line 13, in order_created
    mail_sent = send_mail(subject, message, 'admin@buy_it.com', {order.email})
  File "/home/skydata/buy_it/env/lib/python3.8/site-packages/django/core/mail/__init__.py", line 61, in send_mail
    return mail.send()
  File "/home/skydata/buy_it/env/lib/python3.8/site-packages/django/core/mail/message.py", line 284, in send
    return self.get_connection(fail_silently).send_messages([self])
  File "/home/skydata/buy_it/env/lib/python3.8/site-packages/django/core/mail/backends/smtp.py", line 102, in send_messages
    new_conn_created = self.open()
  File "/home/skydata/buy_it/env/lib/python3.8/site-packages/django/core/mail/backends/smtp.py", line 69, in open
    self.connection.login(self.username, self.password)
  File "/usr/lib/python3.8/smtplib.py", line 734, in login
    raise last_exception
  File "/usr/lib/python3.8/smtplib.py", line 723, in login
    (code, resp) = self.auth(
  File "/usr/lib/python3.8/smtplib.py", line 646, in auth
    raise SMTPAuthenticationError(code, resp)
smtplib.SMTPAuthenticationError: (534, b'5.7.14 <https://accounts.google.com/signin/continue?sarp=1&scc=1&plt=AKgnsbv\n5.7.14 jBwNBMKOgWAB5sRDAUr5s4V26MXDmfaWYkm_TLIQBI-RHHgVcvwGwPHe9Ix0yPHhNsPd8\n5.7.14 nwJXxN_DVPYjg8d4kJd7BWGqsWFxRozNSbQ45N47j-VGpacOpJtTtJ3HQyjAFiun>\n5.7.14 Please log in via your web browser and then try again.\n5.7.14  Learn more at\n5.7.14  https://support.google.com/mail/answer/78754 p10sm12651798wre.84 - gsmtp')
[2021-05-03 18:09:25,489: INFO/MainProcess] Connected to amqp://guest:**@127.0.0.1:5672//
[2021-05-03 18:09:25,499: INFO/MainProcess] mingle: searching for neighbors
[2021-05-03 18:09:26,579: INFO/MainProcess] mingle: all alone
[2021-05-03 18:09:26,605: WARNING/MainProcess] /home/skydata/buy_it/env/lib/python3.8/site-packages/celery/fixups/django.py:205: UserWarning: Using settings.DEBUG leads to a memory
            leak, never use this setting in production environments!
  warnings.warn('''Using settings.DEBUG leads to a memory
[2021-05-03 18:09:26,605: INFO/MainProcess] celery@skydata-Latitude-E5430-non-vPro ready.
[2021-05-06 22:51:57,993: WARNING/MainProcess] consumer: Connection to broker lost. Trying to re-establish the connection...
Traceback (most recent call last):
  File "/home/skydata/buy_it/env/lib/python3.8/site-packages/celery/worker/consumer/consumer.py", line 318, in start
    blueprint.start(self)
  File "/home/skydata/buy_it/env/lib/python3.8/site-packages/celery/bootsteps.py", line 119, in start
    step.start(parent)
  File "/home/skydata/buy_it/env/lib/python3.8/site-packages/celery/worker/consumer/consumer.py", line 599, in start
    c.loop(*c.loop_args())
  File "/home/skydata/buy_it/env/lib/python3.8/site-packages/celery/worker/loops.py", line 83, in asynloop
    next(loop)
  File "/home/skydata/buy_it/env/lib/python3.8/site-packages/kombu/asynchronous/hub.py", line 364, in create_loop
    cb(*cbargs)
  File "/home/skydata/buy_it/env/lib/python3.8/site-packages/kombu/transport/base.py", line 238, in on_readable
    reader(loop)
  File "/home/skydata/buy_it/env/lib/python3.8/site-packages/kombu/transport/base.py", line 220, in _read
    drain_events(timeout=0)
  File "/home/skydata/buy_it/env/lib/python3.8/site-packages/amqp/connection.py", line 508, in drain_events
    while not self.blocking_read(timeout):
  File "/home/skydata/buy_it/env/lib/python3.8/site-packages/amqp/connection.py", line 514, in blocking_read
    return self.on_inbound_frame(frame)
  File "/home/skydata/buy_it/env/lib/python3.8/site-packages/amqp/method_framing.py", line 55, in on_frame
    callback(channel, method_sig, buf, None)
  File "/home/skydata/buy_it/env/lib/python3.8/site-packages/amqp/connection.py", line 520, in on_inbound_method
    return self.channels[channel_id].dispatch_method(
  File "/home/skydata/buy_it/env/lib/python3.8/site-packages/amqp/abstract_channel.py", line 145, in dispatch_method
    listener(*args)
  File "/home/skydata/buy_it/env/lib/python3.8/site-packages/amqp/connection.py", line 649, in _on_close
    self._x_close_ok()
  File "/home/skydata/buy_it/env/lib/python3.8/site-packages/amqp/connection.py", line 664, in _x_close_ok
    self.send_method(spec.Connection.CloseOk, callback=self._on_close_ok)
  File "/home/skydata/buy_it/env/lib/python3.8/site-packages/amqp/abstract_channel.py", line 59, in send_method
    conn.frame_writer(1, self.channel_id, sig, args, content)
  File "/home/skydata/buy_it/env/lib/python3.8/site-packages/amqp/method_framing.py", line 189, in write_frame
    write(view[:offset])
  File "/home/skydata/buy_it/env/lib/python3.8/site-packages/amqp/transport.py", line 305, in write
    self._write(s)
ConnectionResetError: [Errno 104] Connection reset by peer
[2021-05-06 22:51:58,775: ERROR/MainProcess] consumer: Cannot connect to amqp://guest:**@127.0.0.1:5672//: [Errno 111] Connection refused.
Trying again in 2.00 seconds... (1/100)

[2021-05-06 22:52:00,791: ERROR/MainProcess] consumer: Cannot connect to amqp://guest:**@127.0.0.1:5672//: [Errno 111] Connection refused.
Trying again in 4.00 seconds... (2/100)


worker: Warm shutdown (MainProcess)
 
 -------------- celery@skydata-Latitude-E5430-non-vPro v4.4.7 (cliffs)
--- ***** ----- 
-- ******* ---- Linux-5.4.0-70-generic-x86_64-with-glibc2.29 2021-05-03 18:09:25
- *** --- * --- 
- ** ---------- [config]
- ** ---------- .> app:         buy_it:0x7f1198e1d430
- ** ---------- .> transport:   amqp://guest:**@localhost:5672//
- ** ---------- .> results:     disabled://
- *** --- * --- .> concurrency: 4 (prefork)
-- ******* ---- .> task events: OFF (enable -E to monitor tasks in this worker)
--- ***** ----- 
 -------------- [queues]
                .> celery           exchange=celery(direct) key=celery
                

[tasks]
  . orders.tasks.order_created

[2021-05-06 22:54:44,386: INFO/MainProcess] Connected to amqp://guest:**@127.0.0.1:5672//
[2021-05-06 22:54:44,395: INFO/MainProcess] mingle: searching for neighbors
[2021-05-06 22:54:45,465: INFO/MainProcess] mingle: all alone
[2021-05-06 22:54:45,501: INFO/MainProcess] celery@skydata-Latitude-E5430-non-vPro ready.
[2021-05-07 20:10:10,930: INFO/MainProcess] Connected to amqp://guest:**@127.0.0.1:5672//
[2021-05-07 20:10:10,942: INFO/MainProcess] mingle: searching for neighbors
[2021-05-07 20:10:12,015: INFO/MainProcess] mingle: all alone
[2021-05-07 20:10:12,054: WARNING/MainProcess] /home/skydata/buy_it/env/lib/python3.8/site-packages/celery/fixups/django.py:205: UserWarning: Using settings.DEBUG leads to a memory
            leak, never use this setting in production environments!
  warnings.warn('''Using settings.DEBUG leads to a memory
[2021-05-07 20:10:12,054: INFO/MainProcess] celery@skydata-Latitude-E5430-non-vPro ready.

worker: Warm shutdown (MainProcess)
 
 -------------- celery@skydata-Latitude-E5430-non-vPro v4.4.7 (cliffs)
--- ***** ----- 
-- ******* ---- Linux-5.4.0-70-generic-x86_64-with-glibc2.29 2021-05-07 20:10:10
- *** --- * --- 
- ** ---------- [config]
- ** ---------- .> app:         buy_it:0x7fbf842484c0
- ** ---------- .> transport:   amqp://guest:**@localhost:5672//
- ** ---------- .> results:     disabled://
- *** --- * --- .> concurrency: 4 (prefork)
-- ******* ---- .> task events: OFF (enable -E to monitor tasks in this worker)
--- ***** ----- 
 -------------- [queues]
                .> celery           exchange=celery(direct) key=celery
                

[tasks]
  . orders.tasks.order_created

[2021-05-09 15:09:09,742: INFO/MainProcess] Connected to amqp://guest:**@127.0.0.1:5672//
[2021-05-09 15:09:09,752: INFO/MainProcess] mingle: searching for neighbors
[2021-05-09 15:09:10,865: INFO/MainProcess] mingle: all alone
[2021-05-09 15:09:10,894: WARNING/MainProcess] /home/skydata/buy_it/env/lib/python3.8/site-packages/celery/fixups/django.py:205: UserWarning: Using settings.DEBUG leads to a memory
            leak, never use this setting in production environments!
  warnings.warn('''Using settings.DEBUG leads to a memory
[2021-05-09 15:09:10,894: INFO/MainProcess] celery@skydata-Latitude-E5430-non-vPro ready.
[2021-05-16 12:05:39,962: INFO/MainProcess] Connected to amqp://guest:**@127.0.0.1:5672//
[2021-05-16 12:05:39,972: INFO/MainProcess] mingle: searching for neighbors
[2021-05-16 12:05:41,038: INFO/MainProcess] mingle: all alone
[2021-05-16 12:05:41,073: WARNING/MainProcess] /home/skydata/buy_it/env/lib/python3.8/site-packages/celery/fixups/django.py:205: UserWarning: Using settings.DEBUG leads to a memory
            leak, never use this setting in production environments!
  warnings.warn('''Using settings.DEBUG leads to a memory
[2021-05-16 12:05:41,074: INFO/MainProcess] celery@skydata-Latitude-E5430-non-vPro ready.
[2021-05-19 14:24:44,308: INFO/MainProcess] Connected to amqp://guest:**@127.0.0.1:5672//
[2021-05-19 14:24:44,321: INFO/MainProcess] mingle: searching for neighbors
[2021-05-19 14:24:45,381: INFO/MainProcess] mingle: all alone
[2021-05-19 14:24:45,424: WARNING/MainProcess] /home/skydata/buy_it/env/lib/python3.8/site-packages/celery/fixups/django.py:205: UserWarning: Using settings.DEBUG leads to a memory
            leak, never use this setting in production environments!
  warnings.warn('''Using settings.DEBUG leads to a memory
[2021-05-19 14:24:45,425: INFO/MainProcess] celery@skydata-Latitude-E5430-non-vPro ready.
[2021-05-22 01:25:52,613: INFO/MainProcess] Connected to amqp://guest:**@127.0.0.1:5672//
[2021-05-22 01:25:52,627: INFO/MainProcess] mingle: searching for neighbors
[2021-05-22 01:25:53,713: INFO/MainProcess] mingle: all alone
[2021-05-22 01:25:53,752: WARNING/MainProcess] /home/skydata/buy_it/env/lib/python3.8/site-packages/celery/fixups/django.py:205: UserWarning: Using settings.DEBUG leads to a memory
            leak, never use this setting in production environments!
  warnings.warn('''Using settings.DEBUG leads to a memory
[2021-05-22 01:25:53,753: INFO/MainProcess] celery@skydata-Latitude-E5430-non-vPro ready.
[2021-05-23 08:31:39,025: INFO/MainProcess] Connected to amqp://guest:**@127.0.0.1:5672//
[2021-05-23 08:31:39,037: INFO/MainProcess] mingle: searching for neighbors
[2021-05-23 08:31:40,120: INFO/MainProcess] mingle: all alone
[2021-05-23 08:31:40,158: WARNING/MainProcess] /home/skydata/buy_it/env/lib/python3.8/site-packages/celery/fixups/django.py:205: UserWarning: Using settings.DEBUG leads to a memory
            leak, never use this setting in production environments!
  warnings.warn('''Using settings.DEBUG leads to a memory
[2021-05-23 08:31:40,158: INFO/MainProcess] celery@skydata-Latitude-E5430-non-vPro ready.
[2021-05-23 20:08:58,359: INFO/MainProcess] Connected to amqp://guest:**@127.0.0.1:5672//
[2021-05-23 20:08:58,369: INFO/MainProcess] mingle: searching for neighbors
[2021-05-23 20:08:59,434: INFO/MainProcess] mingle: all alone
[2021-05-23 20:08:59,469: WARNING/MainProcess] /home/skydata/buy_it/env/lib/python3.8/site-packages/celery/fixups/django.py:205: UserWarning: Using settings.DEBUG leads to a memory
            leak, never use this setting in production environments!
  warnings.warn('''Using settings.DEBUG leads to a memory
[2021-05-23 20:08:59,469: INFO/MainProcess] celery@skydata-Latitude-E5430-non-vPro ready.
Traceback (most recent call last):
  File "/home/skydata/buy_it/env/lib/python3.8/site-packages/kombu/utils/objects.py", line 42, in __get__
    return obj.__dict__[self.__name__]
KeyError: 'data'

During handling of the above exception, another exception occurred:

Traceback (most recent call last):
  File "/home/skydata/buy_it/env/bin/celery", line 8, in <module>
    sys.exit(main())
  File "/home/skydata/buy_it/env/lib/python3.8/site-packages/celery/__main__.py", line 16, in main
    _main()
  File "/home/skydata/buy_it/env/lib/python3.8/site-packages/celery/bin/celery.py", line 322, in main
    cmd.execute_from_commandline(argv)
  File "/home/skydata/buy_it/env/lib/python3.8/site-packages/celery/bin/celery.py", line 499, in execute_from_commandline
    super(CeleryCommand, self).execute_from_commandline(argv)))
  File "/home/skydata/buy_it/env/lib/python3.8/site-packages/celery/bin/base.py", line 305, in execute_from_commandline
    return self.handle_argv(self.prog_name, argv[1:])
  File "/home/skydata/buy_it/env/lib/python3.8/site-packages/celery/bin/celery.py", line 491, in handle_argv
    return self.execute(command, argv)
  File "/home/skydata/buy_it/env/lib/python3.8/site-packages/celery/bin/celery.py", line 415, in execute
    return cls(
  File "/home/skydata/buy_it/env/lib/python3.8/site-packages/celery/bin/worker.py", line 221, in run_from_argv
    *self.parse_options(prog_name, argv, command))
  File "/home/skydata/buy_it/env/lib/python3.8/site-packages/celery/bin/base.py", line 428, in parse_options
    self.parser = self.create_parser(prog_name, command)
  File "/home/skydata/buy_it/env/lib/python3.8/site-packages/celery/bin/base.py", line 444, in create_parser
    self.add_arguments(parser)
  File "/home/skydata/buy_it/env/lib/python3.8/site-packages/celery/bin/worker.py", line 278, in add_arguments
    default=conf.worker_state_db,
  File "/home/skydata/buy_it/env/lib/python3.8/site-packages/celery/utils/collections.py", line 134, in __getattr__
    return self[k]
  File "/home/skydata/buy_it/env/lib/python3.8/site-packages/celery/utils/collections.py", line 444, in __getitem__
    return getitem(k)
  File "/home/skydata/buy_it/env/lib/python3.8/site-packages/celery/utils/collections.py", line 287, in __getitem__
    return mapping[_key]
  File "/usr/lib/python3.8/collections/__init__.py", line 1006, in __getitem__
    if key in self.data:
  File "/home/skydata/buy_it/env/lib/python3.8/site-packages/kombu/utils/objects.py", line 44, in __get__
    value = obj.__dict__[self.__name__] = self.__get(obj)
  File "/home/skydata/buy_it/env/lib/python3.8/site-packages/celery/app/base.py", line 141, in data
    return self.callback()
  File "/home/skydata/buy_it/env/lib/python3.8/site-packages/celery/app/base.py", line 920, in _finalize_pending_conf
    conf = self._conf = self._load_config()
  File "/home/skydata/buy_it/env/lib/python3.8/site-packages/celery/app/base.py", line 930, in _load_config
    self.loader.config_from_object(self._config_source)
  File "/home/skydata/buy_it/env/lib/python3.8/site-packages/celery/loaders/base.py", line 131, in config_from_object
    self._conf = force_mapping(obj)
  File "/home/skydata/buy_it/env/lib/python3.8/site-packages/celery/utils/collections.py", line 54, in force_mapping
    if isinstance(m, (LazyObject, LazySettings)):
  File "/home/skydata/buy_it/env/lib/python3.8/site-packages/django/utils/functional.py", line 240, in inner
    self._setup()
  File "/home/skydata/buy_it/env/lib/python3.8/site-packages/django/conf/__init__.py", line 70, in _setup
    self._wrapped = Settings(settings_module)
  File "/home/skydata/buy_it/env/lib/python3.8/site-packages/django/conf/__init__.py", line 177, in __init__
    mod = importlib.import_module(self.SETTINGS_MODULE)
  File "/usr/lib/python3.8/importlib/__init__.py", line 127, in import_module
    return _bootstrap._gcd_import(name[level:], package, level)
  File "<frozen importlib._bootstrap>", line 1014, in _gcd_import
  File "<frozen importlib._bootstrap>", line 991, in _find_and_load
  File "<frozen importlib._bootstrap>", line 975, in _find_and_load_unlocked
  File "<frozen importlib._bootstrap>", line 671, in _load_unlocked
  File "<frozen importlib._bootstrap_external>", line 783, in exec_module
  File "<frozen importlib._bootstrap>", line 219, in _call_with_frames_removed
  File "/home/skydata/buy_it/src/buy_it/settings.py", line 15, in <module>
    from decouple import config
ImportError: cannot import name 'config' from 'decouple' (/home/skydata/buy_it/env/lib/python3.8/site-packages/decouple/__init__.py)
Traceback (most recent call last):
  File "/home/skydata/buy_it/env/lib/python3.8/site-packages/kombu/utils/objects.py", line 42, in __get__
    return obj.__dict__[self.__name__]
KeyError: 'data'

During handling of the above exception, another exception occurred:

Traceback (most recent call last):
  File "/home/skydata/buy_it/env/bin/celery", line 8, in <module>
    sys.exit(main())
  File "/home/skydata/buy_it/env/lib/python3.8/site-packages/celery/__main__.py", line 16, in main
    _main()
  File "/home/skydata/buy_it/env/lib/python3.8/site-packages/celery/bin/celery.py", line 322, in main
    cmd.execute_from_commandline(argv)
  File "/home/skydata/buy_it/env/lib/python3.8/site-packages/celery/bin/celery.py", line 499, in execute_from_commandline
    super(CeleryCommand, self).execute_from_commandline(argv)))
  File "/home/skydata/buy_it/env/lib/python3.8/site-packages/celery/bin/base.py", line 305, in execute_from_commandline
    return self.handle_argv(self.prog_name, argv[1:])
  File "/home/skydata/buy_it/env/lib/python3.8/site-packages/celery/bin/celery.py", line 491, in handle_argv
    return self.execute(command, argv)
  File "/home/skydata/buy_it/env/lib/python3.8/site-packages/celery/bin/celery.py", line 415, in execute
    return cls(
  File "/home/skydata/buy_it/env/lib/python3.8/site-packages/celery/bin/worker.py", line 221, in run_from_argv
    *self.parse_options(prog_name, argv, command))
  File "/home/skydata/buy_it/env/lib/python3.8/site-packages/celery/bin/base.py", line 428, in parse_options
    self.parser = self.create_parser(prog_name, command)
  File "/home/skydata/buy_it/env/lib/python3.8/site-packages/celery/bin/base.py", line 444, in create_parser
    self.add_arguments(parser)
  File "/home/skydata/buy_it/env/lib/python3.8/site-packages/celery/bin/worker.py", line 278, in add_arguments
    default=conf.worker_state_db,
  File "/home/skydata/buy_it/env/lib/python3.8/site-packages/celery/utils/collections.py", line 134, in __getattr__
    return self[k]
  File "/home/skydata/buy_it/env/lib/python3.8/site-packages/celery/utils/collections.py", line 444, in __getitem__
    return getitem(k)
  File "/home/skydata/buy_it/env/lib/python3.8/site-packages/celery/utils/collections.py", line 287, in __getitem__
    return mapping[_key]
  File "/usr/lib/python3.8/collections/__init__.py", line 1006, in __getitem__
    if key in self.data:
  File "/home/skydata/buy_it/env/lib/python3.8/site-packages/kombu/utils/objects.py", line 44, in __get__
    value = obj.__dict__[self.__name__] = self.__get(obj)
  File "/home/skydata/buy_it/env/lib/python3.8/site-packages/celery/app/base.py", line 141, in data
    return self.callback()
  File "/home/skydata/buy_it/env/lib/python3.8/site-packages/celery/app/base.py", line 920, in _finalize_pending_conf
    conf = self._conf = self._load_config()
  File "/home/skydata/buy_it/env/lib/python3.8/site-packages/celery/app/base.py", line 930, in _load_config
    self.loader.config_from_object(self._config_source)
  File "/home/skydata/buy_it/env/lib/python3.8/site-packages/celery/loaders/base.py", line 131, in config_from_object
    self._conf = force_mapping(obj)
  File "/home/skydata/buy_it/env/lib/python3.8/site-packages/celery/utils/collections.py", line 54, in force_mapping
    if isinstance(m, (LazyObject, LazySettings)):
  File "/home/skydata/buy_it/env/lib/python3.8/site-packages/django/utils/functional.py", line 240, in inner
    self._setup()
  File "/home/skydata/buy_it/env/lib/python3.8/site-packages/django/conf/__init__.py", line 70, in _setup
    self._wrapped = Settings(settings_module)
  File "/home/skydata/buy_it/env/lib/python3.8/site-packages/django/conf/__init__.py", line 177, in __init__
    mod = importlib.import_module(self.SETTINGS_MODULE)
  File "/usr/lib/python3.8/importlib/__init__.py", line 127, in import_module
    return _bootstrap._gcd_import(name[level:], package, level)
  File "<frozen importlib._bootstrap>", line 1014, in _gcd_import
  File "<frozen importlib._bootstrap>", line 991, in _find_and_load
  File "<frozen importlib._bootstrap>", line 975, in _find_and_load_unlocked
  File "<frozen importlib._bootstrap>", line 671, in _load_unlocked
  File "<frozen importlib._bootstrap_external>", line 783, in exec_module
  File "<frozen importlib._bootstrap>", line 219, in _call_with_frames_removed
  File "/home/skydata/buy_it/src/buy_it/settings.py", line 15, in <module>
    from decouple import config
ImportError: cannot import name 'config' from 'decouple' (/home/skydata/buy_it/env/lib/python3.8/site-packages/decouple/__init__.py)
Traceback (most recent call last):
  File "/home/skydata/buy_it/env/lib/python3.8/site-packages/kombu/utils/objects.py", line 42, in __get__
    return obj.__dict__[self.__name__]
KeyError: 'data'

During handling of the above exception, another exception occurred:

Traceback (most recent call last):
  File "/home/skydata/buy_it/env/bin/celery", line 8, in <module>
    sys.exit(main())
  File "/home/skydata/buy_it/env/lib/python3.8/site-packages/celery/__main__.py", line 16, in main
    _main()
  File "/home/skydata/buy_it/env/lib/python3.8/site-packages/celery/bin/celery.py", line 322, in main
    cmd.execute_from_commandline(argv)
  File "/home/skydata/buy_it/env/lib/python3.8/site-packages/celery/bin/celery.py", line 499, in execute_from_commandline
    super(CeleryCommand, self).execute_from_commandline(argv)))
  File "/home/skydata/buy_it/env/lib/python3.8/site-packages/celery/bin/base.py", line 305, in execute_from_commandline
    return self.handle_argv(self.prog_name, argv[1:])
  File "/home/skydata/buy_it/env/lib/python3.8/site-packages/celery/bin/celery.py", line 491, in handle_argv
    return self.execute(command, argv)
  File "/home/skydata/buy_it/env/lib/python3.8/site-packages/celery/bin/celery.py", line 415, in execute
    return cls(
  File "/home/skydata/buy_it/env/lib/python3.8/site-packages/celery/bin/worker.py", line 221, in run_from_argv
    *self.parse_options(prog_name, argv, command))
  File "/home/skydata/buy_it/env/lib/python3.8/site-packages/celery/bin/base.py", line 428, in parse_options
    self.parser = self.create_parser(prog_name, command)
  File "/home/skydata/buy_it/env/lib/python3.8/site-packages/celery/bin/base.py", line 444, in create_parser
    self.add_arguments(parser)
  File "/home/skydata/buy_it/env/lib/python3.8/site-packages/celery/bin/worker.py", line 278, in add_arguments
    default=conf.worker_state_db,
  File "/home/skydata/buy_it/env/lib/python3.8/site-packages/celery/utils/collections.py", line 134, in __getattr__
    return self[k]
  File "/home/skydata/buy_it/env/lib/python3.8/site-packages/celery/utils/collections.py", line 444, in __getitem__
    return getitem(k)
  File "/home/skydata/buy_it/env/lib/python3.8/site-packages/celery/utils/collections.py", line 287, in __getitem__
    return mapping[_key]
  File "/usr/lib/python3.8/collections/__init__.py", line 1006, in __getitem__
    if key in self.data:
  File "/home/skydata/buy_it/env/lib/python3.8/site-packages/kombu/utils/objects.py", line 44, in __get__
    value = obj.__dict__[self.__name__] = self.__get(obj)
  File "/home/skydata/buy_it/env/lib/python3.8/site-packages/celery/app/base.py", line 141, in data
    return self.callback()
  File "/home/skydata/buy_it/env/lib/python3.8/site-packages/celery/app/base.py", line 920, in _finalize_pending_conf
    conf = self._conf = self._load_config()
  File "/home/skydata/buy_it/env/lib/python3.8/site-packages/celery/app/base.py", line 930, in _load_config
    self.loader.config_from_object(self._config_source)
  File "/home/skydata/buy_it/env/lib/python3.8/site-packages/celery/loaders/base.py", line 131, in config_from_object
    self._conf = force_mapping(obj)
  File "/home/skydata/buy_it/env/lib/python3.8/site-packages/celery/utils/collections.py", line 54, in force_mapping
    if isinstance(m, (LazyObject, LazySettings)):
  File "/home/skydata/buy_it/env/lib/python3.8/site-packages/django/utils/functional.py", line 240, in inner
    self._setup()
  File "/home/skydata/buy_it/env/lib/python3.8/site-packages/django/conf/__init__.py", line 70, in _setup
    self._wrapped = Settings(settings_module)
  File "/home/skydata/buy_it/env/lib/python3.8/site-packages/django/conf/__init__.py", line 177, in __init__
    mod = importlib.import_module(self.SETTINGS_MODULE)
  File "/usr/lib/python3.8/importlib/__init__.py", line 127, in import_module
    return _bootstrap._gcd_import(name[level:], package, level)
  File "<frozen importlib._bootstrap>", line 1014, in _gcd_import
  File "<frozen importlib._bootstrap>", line 991, in _find_and_load
  File "<frozen importlib._bootstrap>", line 975, in _find_and_load_unlocked
  File "<frozen importlib._bootstrap>", line 671, in _load_unlocked
  File "<frozen importlib._bootstrap_external>", line 783, in exec_module
  File "<frozen importlib._bootstrap>", line 219, in _call_with_frames_removed
  File "/home/skydata/buy_it/src/buy_it/settings.py", line 15, in <module>
    from decouple import config
ImportError: cannot import name 'config' from 'decouple' (/home/skydata/buy_it/env/lib/python3.8/site-packages/decouple/__init__.py)
Traceback (most recent call last):
  File "/home/skydata/buy_it/env/lib/python3.8/site-packages/kombu/utils/objects.py", line 42, in __get__
    return obj.__dict__[self.__name__]
KeyError: 'data'

During handling of the above exception, another exception occurred:

Traceback (most recent call last):
  File "/home/skydata/buy_it/env/bin/celery", line 8, in <module>
    sys.exit(main())
  File "/home/skydata/buy_it/env/lib/python3.8/site-packages/celery/__main__.py", line 16, in main
    _main()
  File "/home/skydata/buy_it/env/lib/python3.8/site-packages/celery/bin/celery.py", line 322, in main
    cmd.execute_from_commandline(argv)
  File "/home/skydata/buy_it/env/lib/python3.8/site-packages/celery/bin/celery.py", line 499, in execute_from_commandline
    super(CeleryCommand, self).execute_from_commandline(argv)))
  File "/home/skydata/buy_it/env/lib/python3.8/site-packages/celery/bin/base.py", line 305, in execute_from_commandline
    return self.handle_argv(self.prog_name, argv[1:])
  File "/home/skydata/buy_it/env/lib/python3.8/site-packages/celery/bin/celery.py", line 491, in handle_argv
    return self.execute(command, argv)
  File "/home/skydata/buy_it/env/lib/python3.8/site-packages/celery/bin/celery.py", line 415, in execute
    return cls(
  File "/home/skydata/buy_it/env/lib/python3.8/site-packages/celery/bin/worker.py", line 221, in run_from_argv
    *self.parse_options(prog_name, argv, command))
  File "/home/skydata/buy_it/env/lib/python3.8/site-packages/celery/bin/base.py", line 428, in parse_options
    self.parser = self.create_parser(prog_name, command)
  File "/home/skydata/buy_it/env/lib/python3.8/site-packages/celery/bin/base.py", line 444, in create_parser
    self.add_arguments(parser)
  File "/home/skydata/buy_it/env/lib/python3.8/site-packages/celery/bin/worker.py", line 278, in add_arguments
    default=conf.worker_state_db,
  File "/home/skydata/buy_it/env/lib/python3.8/site-packages/celery/utils/collections.py", line 134, in __getattr__
    return self[k]
  File "/home/skydata/buy_it/env/lib/python3.8/site-packages/celery/utils/collections.py", line 444, in __getitem__
    return getitem(k)
  File "/home/skydata/buy_it/env/lib/python3.8/site-packages/celery/utils/collections.py", line 287, in __getitem__
    return mapping[_key]
  File "/usr/lib/python3.8/collections/__init__.py", line 1006, in __getitem__
    if key in self.data:
  File "/home/skydata/buy_it/env/lib/python3.8/site-packages/kombu/utils/objects.py", line 44, in __get__
    value = obj.__dict__[self.__name__] = self.__get(obj)
  File "/home/skydata/buy_it/env/lib/python3.8/site-packages/celery/app/base.py", line 141, in data
    return self.callback()
  File "/home/skydata/buy_it/env/lib/python3.8/site-packages/celery/app/base.py", line 920, in _finalize_pending_conf
    conf = self._conf = self._load_config()
  File "/home/skydata/buy_it/env/lib/python3.8/site-packages/celery/app/base.py", line 930, in _load_config
    self.loader.config_from_object(self._config_source)
  File "/home/skydata/buy_it/env/lib/python3.8/site-packages/celery/loaders/base.py", line 131, in config_from_object
    self._conf = force_mapping(obj)
  File "/home/skydata/buy_it/env/lib/python3.8/site-packages/celery/utils/collections.py", line 54, in force_mapping
    if isinstance(m, (LazyObject, LazySettings)):
  File "/home/skydata/buy_it/env/lib/python3.8/site-packages/django/utils/functional.py", line 240, in inner
    self._setup()
  File "/home/skydata/buy_it/env/lib/python3.8/site-packages/django/conf/__init__.py", line 70, in _setup
    self._wrapped = Settings(settings_module)
  File "/home/skydata/buy_it/env/lib/python3.8/site-packages/django/conf/__init__.py", line 177, in __init__
    mod = importlib.import_module(self.SETTINGS_MODULE)
  File "/usr/lib/python3.8/importlib/__init__.py", line 127, in import_module
    return _bootstrap._gcd_import(name[level:], package, level)
  File "<frozen importlib._bootstrap>", line 1014, in _gcd_import
  File "<frozen importlib._bootstrap>", line 991, in _find_and_load
  File "<frozen importlib._bootstrap>", line 975, in _find_and_load_unlocked
  File "<frozen importlib._bootstrap>", line 671, in _load_unlocked
  File "<frozen importlib._bootstrap_external>", line 783, in exec_module
  File "<frozen importlib._bootstrap>", line 219, in _call_with_frames_removed
  File "/home/skydata/buy_it/src/buy_it/settings.py", line 15, in <module>
    from decouple import config
ImportError: cannot import name 'config' from 'decouple' (/home/skydata/buy_it/env/lib/python3.8/site-packages/decouple/__init__.py)
Traceback (most recent call last):
  File "/home/skydata/buy_it/env/lib/python3.8/site-packages/kombu/utils/objects.py", line 42, in __get__
    return obj.__dict__[self.__name__]
KeyError: 'data'

During handling of the above exception, another exception occurred:

Traceback (most recent call last):
  File "/home/skydata/buy_it/env/bin/celery", line 8, in <module>
    sys.exit(main())
  File "/home/skydata/buy_it/env/lib/python3.8/site-packages/celery/__main__.py", line 16, in main
    _main()
  File "/home/skydata/buy_it/env/lib/python3.8/site-packages/celery/bin/celery.py", line 322, in main
    cmd.execute_from_commandline(argv)
  File "/home/skydata/buy_it/env/lib/python3.8/site-packages/celery/bin/celery.py", line 499, in execute_from_commandline
    super(CeleryCommand, self).execute_from_commandline(argv)))
  File "/home/skydata/buy_it/env/lib/python3.8/site-packages/celery/bin/base.py", line 305, in execute_from_commandline
    return self.handle_argv(self.prog_name, argv[1:])
  File "/home/skydata/buy_it/env/lib/python3.8/site-packages/celery/bin/celery.py", line 491, in handle_argv
    return self.execute(command, argv)
  File "/home/skydata/buy_it/env/lib/python3.8/site-packages/celery/bin/celery.py", line 415, in execute
    return cls(
  File "/home/skydata/buy_it/env/lib/python3.8/site-packages/celery/bin/worker.py", line 221, in run_from_argv
    *self.parse_options(prog_name, argv, command))
  File "/home/skydata/buy_it/env/lib/python3.8/site-packages/celery/bin/base.py", line 428, in parse_options
    self.parser = self.create_parser(prog_name, command)
  File "/home/skydata/buy_it/env/lib/python3.8/site-packages/celery/bin/base.py", line 444, in create_parser
    self.add_arguments(parser)
  File "/home/skydata/buy_it/env/lib/python3.8/site-packages/celery/bin/worker.py", line 278, in add_arguments
    default=conf.worker_state_db,
  File "/home/skydata/buy_it/env/lib/python3.8/site-packages/celery/utils/collections.py", line 134, in __getattr__
    return self[k]
  File "/home/skydata/buy_it/env/lib/python3.8/site-packages/celery/utils/collections.py", line 444, in __getitem__
    return getitem(k)
  File "/home/skydata/buy_it/env/lib/python3.8/site-packages/celery/utils/collections.py", line 287, in __getitem__
    return mapping[_key]
  File "/usr/lib/python3.8/collections/__init__.py", line 1006, in __getitem__
    if key in self.data:
  File "/home/skydata/buy_it/env/lib/python3.8/site-packages/kombu/utils/objects.py", line 44, in __get__
    value = obj.__dict__[self.__name__] = self.__get(obj)
  File "/home/skydata/buy_it/env/lib/python3.8/site-packages/celery/app/base.py", line 141, in data
    return self.callback()
  File "/home/skydata/buy_it/env/lib/python3.8/site-packages/celery/app/base.py", line 920, in _finalize_pending_conf
    conf = self._conf = self._load_config()
  File "/home/skydata/buy_it/env/lib/python3.8/site-packages/celery/app/base.py", line 930, in _load_config
    self.loader.config_from_object(self._config_source)
  File "/home/skydata/buy_it/env/lib/python3.8/site-packages/celery/loaders/base.py", line 131, in config_from_object
    self._conf = force_mapping(obj)
  File "/home/skydata/buy_it/env/lib/python3.8/site-packages/celery/utils/collections.py", line 54, in force_mapping
    if isinstance(m, (LazyObject, LazySettings)):
  File "/home/skydata/buy_it/env/lib/python3.8/site-packages/django/utils/functional.py", line 240, in inner
    self._setup()
  File "/home/skydata/buy_it/env/lib/python3.8/site-packages/django/conf/__init__.py", line 70, in _setup
    self._wrapped = Settings(settings_module)
  File "/home/skydata/buy_it/env/lib/python3.8/site-packages/django/conf/__init__.py", line 177, in __init__
    mod = importlib.import_module(self.SETTINGS_MODULE)
  File "/usr/lib/python3.8/importlib/__init__.py", line 127, in import_module
    return _bootstrap._gcd_import(name[level:], package, level)
  File "<frozen importlib._bootstrap>", line 1014, in _gcd_import
  File "<frozen importlib._bootstrap>", line 991, in _find_and_load
  File "<frozen importlib._bootstrap>", line 975, in _find_and_load_unlocked
  File "<frozen importlib._bootstrap>", line 671, in _load_unlocked
  File "<frozen importlib._bootstrap_external>", line 783, in exec_module
  File "<frozen importlib._bootstrap>", line 219, in _call_with_frames_removed
  File "/home/skydata/buy_it/src/buy_it/settings.py", line 15, in <module>
    from decouple import config
ImportError: cannot import name 'config' from 'decouple' (/home/skydata/buy_it/env/lib/python3.8/site-packages/decouple/__init__.py)
Traceback (most recent call last):
  File "/home/skydata/buy_it/env/lib/python3.8/site-packages/kombu/utils/objects.py", line 42, in __get__
    return obj.__dict__[self.__name__]
KeyError: 'data'

During handling of the above exception, another exception occurred:

Traceback (most recent call last):
  File "/home/skydata/buy_it/env/bin/celery", line 8, in <module>
    sys.exit(main())
  File "/home/skydata/buy_it/env/lib/python3.8/site-packages/celery/__main__.py", line 16, in main
    _main()
  File "/home/skydata/buy_it/env/lib/python3.8/site-packages/celery/bin/celery.py", line 322, in main
    cmd.execute_from_commandline(argv)
  File "/home/skydata/buy_it/env/lib/python3.8/site-packages/celery/bin/celery.py", line 499, in execute_from_commandline
    super(CeleryCommand, self).execute_from_commandline(argv)))
  File "/home/skydata/buy_it/env/lib/python3.8/site-packages/celery/bin/base.py", line 305, in execute_from_commandline
    return self.handle_argv(self.prog_name, argv[1:])
  File "/home/skydata/buy_it/env/lib/python3.8/site-packages/celery/bin/celery.py", line 491, in handle_argv
    return self.execute(command, argv)
  File "/home/skydata/buy_it/env/lib/python3.8/site-packages/celery/bin/celery.py", line 415, in execute
    return cls(
  File "/home/skydata/buy_it/env/lib/python3.8/site-packages/celery/bin/worker.py", line 221, in run_from_argv
    *self.parse_options(prog_name, argv, command))
  File "/home/skydata/buy_it/env/lib/python3.8/site-packages/celery/bin/base.py", line 428, in parse_options
    self.parser = self.create_parser(prog_name, command)
  File "/home/skydata/buy_it/env/lib/python3.8/site-packages/celery/bin/base.py", line 444, in create_parser
    self.add_arguments(parser)
  File "/home/skydata/buy_it/env/lib/python3.8/site-packages/celery/bin/worker.py", line 278, in add_arguments
    default=conf.worker_state_db,
  File "/home/skydata/buy_it/env/lib/python3.8/site-packages/celery/utils/collections.py", line 134, in __getattr__
    return self[k]
  File "/home/skydata/buy_it/env/lib/python3.8/site-packages/celery/utils/collections.py", line 444, in __getitem__
    return getitem(k)
  File "/home/skydata/buy_it/env/lib/python3.8/site-packages/celery/utils/collections.py", line 287, in __getitem__
    return mapping[_key]
  File "/usr/lib/python3.8/collections/__init__.py", line 1006, in __getitem__
    if key in self.data:
  File "/home/skydata/buy_it/env/lib/python3.8/site-packages/kombu/utils/objects.py", line 44, in __get__
    value = obj.__dict__[self.__name__] = self.__get(obj)
  File "/home/skydata/buy_it/env/lib/python3.8/site-packages/celery/app/base.py", line 141, in data
    return self.callback()
  File "/home/skydata/buy_it/env/lib/python3.8/site-packages/celery/app/base.py", line 920, in _finalize_pending_conf
    conf = self._conf = self._load_config()
  File "/home/skydata/buy_it/env/lib/python3.8/site-packages/celery/app/base.py", line 930, in _load_config
    self.loader.config_from_object(self._config_source)
  File "/home/skydata/buy_it/env/lib/python3.8/site-packages/celery/loaders/base.py", line 131, in config_from_object
    self._conf = force_mapping(obj)
  File "/home/skydata/buy_it/env/lib/python3.8/site-packages/celery/utils/collections.py", line 54, in force_mapping
    if isinstance(m, (LazyObject, LazySettings)):
  File "/home/skydata/buy_it/env/lib/python3.8/site-packages/django/utils/functional.py", line 240, in inner
    self._setup()
  File "/home/skydata/buy_it/env/lib/python3.8/site-packages/django/conf/__init__.py", line 70, in _setup
    self._wrapped = Settings(settings_module)
  File "/home/skydata/buy_it/env/lib/python3.8/site-packages/django/conf/__init__.py", line 177, in __init__
    mod = importlib.import_module(self.SETTINGS_MODULE)
  File "/usr/lib/python3.8/importlib/__init__.py", line 127, in import_module
    return _bootstrap._gcd_import(name[level:], package, level)
  File "<frozen importlib._bootstrap>", line 1014, in _gcd_import
  File "<frozen importlib._bootstrap>", line 991, in _find_and_load
  File "<frozen importlib._bootstrap>", line 975, in _find_and_load_unlocked
  File "<frozen importlib._bootstrap>", line 671, in _load_unlocked
  File "<frozen importlib._bootstrap_external>", line 783, in exec_module
  File "<frozen importlib._bootstrap>", line 219, in _call_with_frames_removed
  File "/home/skydata/buy_it/src/buy_it/settings.py", line 15, in <module>
    from decouple import config
ImportError: cannot import name 'config' from 'decouple' (/home/skydata/buy_it/env/lib/python3.8/site-packages/decouple/__init__.py)
Traceback (most recent call last):
  File "/home/skydata/buy_it/env/lib/python3.8/site-packages/kombu/utils/objects.py", line 42, in __get__
    return obj.__dict__[self.__name__]
KeyError: 'data'

During handling of the above exception, another exception occurred:

Traceback (most recent call last):
  File "/home/skydata/buy_it/env/bin/celery", line 8, in <module>
    sys.exit(main())
  File "/home/skydata/buy_it/env/lib/python3.8/site-packages/celery/__main__.py", line 16, in main
    _main()
  File "/home/skydata/buy_it/env/lib/python3.8/site-packages/celery/bin/celery.py", line 322, in main
    cmd.execute_from_commandline(argv)
  File "/home/skydata/buy_it/env/lib/python3.8/site-packages/celery/bin/celery.py", line 499, in execute_from_commandline
    super(CeleryCommand, self).execute_from_commandline(argv)))
  File "/home/skydata/buy_it/env/lib/python3.8/site-packages/celery/bin/base.py", line 305, in execute_from_commandline
    return self.handle_argv(self.prog_name, argv[1:])
  File "/home/skydata/buy_it/env/lib/python3.8/site-packages/celery/bin/celery.py", line 491, in handle_argv
    return self.execute(command, argv)
  File "/home/skydata/buy_it/env/lib/python3.8/site-packages/celery/bin/celery.py", line 415, in execute
    return cls(
  File "/home/skydata/buy_it/env/lib/python3.8/site-packages/celery/bin/worker.py", line 221, in run_from_argv
    *self.parse_options(prog_name, argv, command))
  File "/home/skydata/buy_it/env/lib/python3.8/site-packages/celery/bin/base.py", line 428, in parse_options
    self.parser = self.create_parser(prog_name, command)
  File "/home/skydata/buy_it/env/lib/python3.8/site-packages/celery/bin/base.py", line 444, in create_parser
    self.add_arguments(parser)
  File "/home/skydata/buy_it/env/lib/python3.8/site-packages/celery/bin/worker.py", line 278, in add_arguments
    default=conf.worker_state_db,
  File "/home/skydata/buy_it/env/lib/python3.8/site-packages/celery/utils/collections.py", line 134, in __getattr__
    return self[k]
  File "/home/skydata/buy_it/env/lib/python3.8/site-packages/celery/utils/collections.py", line 444, in __getitem__
    return getitem(k)
  File "/home/skydata/buy_it/env/lib/python3.8/site-packages/celery/utils/collections.py", line 287, in __getitem__
    return mapping[_key]
  File "/usr/lib/python3.8/collections/__init__.py", line 1006, in __getitem__
    if key in self.data:
  File "/home/skydata/buy_it/env/lib/python3.8/site-packages/kombu/utils/objects.py", line 44, in __get__
    value = obj.__dict__[self.__name__] = self.__get(obj)
  File "/home/skydata/buy_it/env/lib/python3.8/site-packages/celery/app/base.py", line 141, in data
    return self.callback()
  File "/home/skydata/buy_it/env/lib/python3.8/site-packages/celery/app/base.py", line 920, in _finalize_pending_conf
    conf = self._conf = self._load_config()
  File "/home/skydata/buy_it/env/lib/python3.8/site-packages/celery/app/base.py", line 930, in _load_config
    self.loader.config_from_object(self._config_source)
  File "/home/skydata/buy_it/env/lib/python3.8/site-packages/celery/loaders/base.py", line 131, in config_from_object
    self._conf = force_mapping(obj)
  File "/home/skydata/buy_it/env/lib/python3.8/site-packages/celery/utils/collections.py", line 54, in force_mapping
    if isinstance(m, (LazyObject, LazySettings)):
  File "/home/skydata/buy_it/env/lib/python3.8/site-packages/django/utils/functional.py", line 240, in inner
    self._setup()
  File "/home/skydata/buy_it/env/lib/python3.8/site-packages/django/conf/__init__.py", line 70, in _setup
    self._wrapped = Settings(settings_module)
  File "/home/skydata/buy_it/env/lib/python3.8/site-packages/django/conf/__init__.py", line 177, in __init__
    mod = importlib.import_module(self.SETTINGS_MODULE)
  File "/usr/lib/python3.8/importlib/__init__.py", line 127, in import_module
    return _bootstrap._gcd_import(name[level:], package, level)
  File "<frozen importlib._bootstrap>", line 1014, in _gcd_import
  File "<frozen importlib._bootstrap>", line 991, in _find_and_load
  File "<frozen importlib._bootstrap>", line 975, in _find_and_load_unlocked
  File "<frozen importlib._bootstrap>", line 671, in _load_unlocked
  File "<frozen importlib._bootstrap_external>", line 783, in exec_module
  File "<frozen importlib._bootstrap>", line 219, in _call_with_frames_removed
  File "/home/skydata/buy_it/src/buy_it/settings.py", line 15, in <module>
    from decouple import config
ImportError: cannot import name 'config' from 'decouple' (/home/skydata/buy_it/env/lib/python3.8/site-packages/decouple/__init__.py)
Traceback (most recent call last):
  File "/home/skydata/buy_it/env/lib/python3.8/site-packages/kombu/utils/objects.py", line 42, in __get__
    return obj.__dict__[self.__name__]
KeyError: 'data'

During handling of the above exception, another exception occurred:

Traceback (most recent call last):
  File "/home/skydata/buy_it/env/bin/celery", line 8, in <module>
    sys.exit(main())
  File "/home/skydata/buy_it/env/lib/python3.8/site-packages/celery/__main__.py", line 16, in main
    _main()
  File "/home/skydata/buy_it/env/lib/python3.8/site-packages/celery/bin/celery.py", line 322, in main
    cmd.execute_from_commandline(argv)
  File "/home/skydata/buy_it/env/lib/python3.8/site-packages/celery/bin/celery.py", line 499, in execute_from_commandline
    super(CeleryCommand, self).execute_from_commandline(argv)))
  File "/home/skydata/buy_it/env/lib/python3.8/site-packages/celery/bin/base.py", line 305, in execute_from_commandline
    return self.handle_argv(self.prog_name, argv[1:])
  File "/home/skydata/buy_it/env/lib/python3.8/site-packages/celery/bin/celery.py", line 491, in handle_argv
    return self.execute(command, argv)
  File "/home/skydata/buy_it/env/lib/python3.8/site-packages/celery/bin/celery.py", line 415, in execute
    return cls(
  File "/home/skydata/buy_it/env/lib/python3.8/site-packages/celery/bin/worker.py", line 221, in run_from_argv
    *self.parse_options(prog_name, argv, command))
  File "/home/skydata/buy_it/env/lib/python3.8/site-packages/celery/bin/base.py", line 428, in parse_options
    self.parser = self.create_parser(prog_name, command)
  File "/home/skydata/buy_it/env/lib/python3.8/site-packages/celery/bin/base.py", line 444, in create_parser
    self.add_arguments(parser)
  File "/home/skydata/buy_it/env/lib/python3.8/site-packages/celery/bin/worker.py", line 278, in add_arguments
    default=conf.worker_state_db,
  File "/home/skydata/buy_it/env/lib/python3.8/site-packages/celery/utils/collections.py", line 134, in __getattr__
    return self[k]
  File "/home/skydata/buy_it/env/lib/python3.8/site-packages/celery/utils/collections.py", line 444, in __getitem__
    return getitem(k)
  File "/home/skydata/buy_it/env/lib/python3.8/site-packages/celery/utils/collections.py", line 287, in __getitem__
    return mapping[_key]
  File "/usr/lib/python3.8/collections/__init__.py", line 1006, in __getitem__
    if key in self.data:
  File "/home/skydata/buy_it/env/lib/python3.8/site-packages/kombu/utils/objects.py", line 44, in __get__
    value = obj.__dict__[self.__name__] = self.__get(obj)
  File "/home/skydata/buy_it/env/lib/python3.8/site-packages/celery/app/base.py", line 141, in data
    return self.callback()
  File "/home/skydata/buy_it/env/lib/python3.8/site-packages/celery/app/base.py", line 920, in _finalize_pending_conf
    conf = self._conf = self._load_config()
  File "/home/skydata/buy_it/env/lib/python3.8/site-packages/celery/app/base.py", line 930, in _load_config
    self.loader.config_from_object(self._config_source)
  File "/home/skydata/buy_it/env/lib/python3.8/site-packages/celery/loaders/base.py", line 131, in config_from_object
    self._conf = force_mapping(obj)
  File "/home/skydata/buy_it/env/lib/python3.8/site-packages/celery/utils/collections.py", line 54, in force_mapping
    if isinstance(m, (LazyObject, LazySettings)):
  File "/home/skydata/buy_it/env/lib/python3.8/site-packages/django/utils/functional.py", line 240, in inner
    self._setup()
  File "/home/skydata/buy_it/env/lib/python3.8/site-packages/django/conf/__init__.py", line 70, in _setup
    self._wrapped = Settings(settings_module)
  File "/home/skydata/buy_it/env/lib/python3.8/site-packages/django/conf/__init__.py", line 177, in __init__
    mod = importlib.import_module(self.SETTINGS_MODULE)
  File "/usr/lib/python3.8/importlib/__init__.py", line 127, in import_module
    return _bootstrap._gcd_import(name[level:], package, level)
  File "<frozen importlib._bootstrap>", line 1014, in _gcd_import
  File "<frozen importlib._bootstrap>", line 991, in _find_and_load
  File "<frozen importlib._bootstrap>", line 975, in _find_and_load_unlocked
  File "<frozen importlib._bootstrap>", line 671, in _load_unlocked
  File "<frozen importlib._bootstrap_external>", line 783, in exec_module
  File "<frozen importlib._bootstrap>", line 219, in _call_with_frames_removed
  File "/home/skydata/buy_it/src/buy_it/settings.py", line 15, in <module>
    from decouple import config
ImportError: cannot import name 'config' from 'decouple' (/home/skydata/buy_it/env/lib/python3.8/site-packages/decouple/__init__.py)
Traceback (most recent call last):
  File "/home/skydata/buy_it/env/lib/python3.8/site-packages/kombu/utils/objects.py", line 42, in __get__
    return obj.__dict__[self.__name__]
KeyError: 'data'

During handling of the above exception, another exception occurred:

Traceback (most recent call last):
  File "/home/skydata/buy_it/env/bin/celery", line 8, in <module>
    sys.exit(main())
  File "/home/skydata/buy_it/env/lib/python3.8/site-packages/celery/__main__.py", line 16, in main
    _main()
  File "/home/skydata/buy_it/env/lib/python3.8/site-packages/celery/bin/celery.py", line 322, in main
    cmd.execute_from_commandline(argv)
  File "/home/skydata/buy_it/env/lib/python3.8/site-packages/celery/bin/celery.py", line 499, in execute_from_commandline
    super(CeleryCommand, self).execute_from_commandline(argv)))
  File "/home/skydata/buy_it/env/lib/python3.8/site-packages/celery/bin/base.py", line 305, in execute_from_commandline
    return self.handle_argv(self.prog_name, argv[1:])
  File "/home/skydata/buy_it/env/lib/python3.8/site-packages/celery/bin/celery.py", line 491, in handle_argv
    return self.execute(command, argv)
  File "/home/skydata/buy_it/env/lib/python3.8/site-packages/celery/bin/celery.py", line 415, in execute
    return cls(
  File "/home/skydata/buy_it/env/lib/python3.8/site-packages/celery/bin/worker.py", line 221, in run_from_argv
    *self.parse_options(prog_name, argv, command))
  File "/home/skydata/buy_it/env/lib/python3.8/site-packages/celery/bin/base.py", line 428, in parse_options
    self.parser = self.create_parser(prog_name, command)
  File "/home/skydata/buy_it/env/lib/python3.8/site-packages/celery/bin/base.py", line 444, in create_parser
    self.add_arguments(parser)
  File "/home/skydata/buy_it/env/lib/python3.8/site-packages/celery/bin/worker.py", line 278, in add_arguments
    default=conf.worker_state_db,
  File "/home/skydata/buy_it/env/lib/python3.8/site-packages/celery/utils/collections.py", line 134, in __getattr__
    return self[k]
  File "/home/skydata/buy_it/env/lib/python3.8/site-packages/celery/utils/collections.py", line 444, in __getitem__
    return getitem(k)
  File "/home/skydata/buy_it/env/lib/python3.8/site-packages/celery/utils/collections.py", line 287, in __getitem__
    return mapping[_key]
  File "/usr/lib/python3.8/collections/__init__.py", line 1006, in __getitem__
    if key in self.data:
  File "/home/skydata/buy_it/env/lib/python3.8/site-packages/kombu/utils/objects.py", line 44, in __get__
    value = obj.__dict__[self.__name__] = self.__get(obj)
  File "/home/skydata/buy_it/env/lib/python3.8/site-packages/celery/app/base.py", line 141, in data
    return self.callback()
  File "/home/skydata/buy_it/env/lib/python3.8/site-packages/celery/app/base.py", line 920, in _finalize_pending_conf
    conf = self._conf = self._load_config()
  File "/home/skydata/buy_it/env/lib/python3.8/site-packages/celery/app/base.py", line 930, in _load_config
    self.loader.config_from_object(self._config_source)
  File "/home/skydata/buy_it/env/lib/python3.8/site-packages/celery/loaders/base.py", line 131, in config_from_object
    self._conf = force_mapping(obj)
  File "/home/skydata/buy_it/env/lib/python3.8/site-packages/celery/utils/collections.py", line 54, in force_mapping
    if isinstance(m, (LazyObject, LazySettings)):
  File "/home/skydata/buy_it/env/lib/python3.8/site-packages/django/utils/functional.py", line 240, in inner
    self._setup()
  File "/home/skydata/buy_it/env/lib/python3.8/site-packages/django/conf/__init__.py", line 70, in _setup
    self._wrapped = Settings(settings_module)
  File "/home/skydata/buy_it/env/lib/python3.8/site-packages/django/conf/__init__.py", line 177, in __init__
    mod = importlib.import_module(self.SETTINGS_MODULE)
  File "/usr/lib/python3.8/importlib/__init__.py", line 127, in import_module
    return _bootstrap._gcd_import(name[level:], package, level)
  File "<frozen importlib._bootstrap>", line 1014, in _gcd_import
  File "<frozen importlib._bootstrap>", line 991, in _find_and_load
  File "<frozen importlib._bootstrap>", line 975, in _find_and_load_unlocked
  File "<frozen importlib._bootstrap>", line 671, in _load_unlocked
  File "<frozen importlib._bootstrap_external>", line 783, in exec_module
  File "<frozen importlib._bootstrap>", line 219, in _call_with_frames_removed
  File "/home/skydata/buy_it/src/buy_it/settings.py", line 15, in <module>
    from decouple import config
ImportError: cannot import name 'config' from 'decouple' (/home/skydata/buy_it/env/lib/python3.8/site-packages/decouple/__init__.py)
Traceback (most recent call last):
  File "/home/skydata/buy_it/env/lib/python3.8/site-packages/kombu/utils/objects.py", line 42, in __get__
    return obj.__dict__[self.__name__]
KeyError: 'data'

During handling of the above exception, another exception occurred:

Traceback (most recent call last):
  File "/home/skydata/buy_it/env/bin/celery", line 8, in <module>
    sys.exit(main())
  File "/home/skydata/buy_it/env/lib/python3.8/site-packages/celery/__main__.py", line 16, in main
    _main()
  File "/home/skydata/buy_it/env/lib/python3.8/site-packages/celery/bin/celery.py", line 322, in main
    cmd.execute_from_commandline(argv)
  File "/home/skydata/buy_it/env/lib/python3.8/site-packages/celery/bin/celery.py", line 499, in execute_from_commandline
    super(CeleryCommand, self).execute_from_commandline(argv)))
  File "/home/skydata/buy_it/env/lib/python3.8/site-packages/celery/bin/base.py", line 305, in execute_from_commandline
    return self.handle_argv(self.prog_name, argv[1:])
  File "/home/skydata/buy_it/env/lib/python3.8/site-packages/celery/bin/celery.py", line 491, in handle_argv
    return self.execute(command, argv)
  File "/home/skydata/buy_it/env/lib/python3.8/site-packages/celery/bin/celery.py", line 415, in execute
    return cls(
  File "/home/skydata/buy_it/env/lib/python3.8/site-packages/celery/bin/worker.py", line 221, in run_from_argv
    *self.parse_options(prog_name, argv, command))
  File "/home/skydata/buy_it/env/lib/python3.8/site-packages/celery/bin/base.py", line 428, in parse_options
    self.parser = self.create_parser(prog_name, command)
  File "/home/skydata/buy_it/env/lib/python3.8/site-packages/celery/bin/base.py", line 444, in create_parser
    self.add_arguments(parser)
  File "/home/skydata/buy_it/env/lib/python3.8/site-packages/celery/bin/worker.py", line 278, in add_arguments
    default=conf.worker_state_db,
  File "/home/skydata/buy_it/env/lib/python3.8/site-packages/celery/utils/collections.py", line 134, in __getattr__
    return self[k]
  File "/home/skydata/buy_it/env/lib/python3.8/site-packages/celery/utils/collections.py", line 444, in __getitem__
    return getitem(k)
  File "/home/skydata/buy_it/env/lib/python3.8/site-packages/celery/utils/collections.py", line 287, in __getitem__
    return mapping[_key]
  File "/usr/lib/python3.8/collections/__init__.py", line 1006, in __getitem__
    if key in self.data:
  File "/home/skydata/buy_it/env/lib/python3.8/site-packages/kombu/utils/objects.py", line 44, in __get__
    value = obj.__dict__[self.__name__] = self.__get(obj)
  File "/home/skydata/buy_it/env/lib/python3.8/site-packages/celery/app/base.py", line 141, in data
    return self.callback()
  File "/home/skydata/buy_it/env/lib/python3.8/site-packages/celery/app/base.py", line 920, in _finalize_pending_conf
    conf = self._conf = self._load_config()
  File "/home/skydata/buy_it/env/lib/python3.8/site-packages/celery/app/base.py", line 930, in _load_config
    self.loader.config_from_object(self._config_source)
  File "/home/skydata/buy_it/env/lib/python3.8/site-packages/celery/loaders/base.py", line 131, in config_from_object
    self._conf = force_mapping(obj)
  File "/home/skydata/buy_it/env/lib/python3.8/site-packages/celery/utils/collections.py", line 54, in force_mapping
    if isinstance(m, (LazyObject, LazySettings)):
  File "/home/skydata/buy_it/env/lib/python3.8/site-packages/django/utils/functional.py", line 240, in inner
    self._setup()
  File "/home/skydata/buy_it/env/lib/python3.8/site-packages/django/conf/__init__.py", line 70, in _setup
    self._wrapped = Settings(settings_module)
  File "/home/skydata/buy_it/env/lib/python3.8/site-packages/django/conf/__init__.py", line 177, in __init__
    mod = importlib.import_module(self.SETTINGS_MODULE)
  File "/usr/lib/python3.8/importlib/__init__.py", line 127, in import_module
    return _bootstrap._gcd_import(name[level:], package, level)
  File "<frozen importlib._bootstrap>", line 1014, in _gcd_import
  File "<frozen importlib._bootstrap>", line 991, in _find_and_load
  File "<frozen importlib._bootstrap>", line 975, in _find_and_load_unlocked
  File "<frozen importlib._bootstrap>", line 671, in _load_unlocked
  File "<frozen importlib._bootstrap_external>", line 783, in exec_module
  File "<frozen importlib._bootstrap>", line 219, in _call_with_frames_removed
  File "/home/skydata/buy_it/src/buy_it/settings.py", line 15, in <module>
    from decouple import config
ImportError: cannot import name 'config' from 'decouple' (/home/skydata/buy_it/env/lib/python3.8/site-packages/decouple/__init__.py)
[2021-05-27 15:16:53,383: INFO/MainProcess] Connected to amqp://guest:**@127.0.0.1:5672//
[2021-05-27 15:16:53,394: INFO/MainProcess] mingle: searching for neighbors
[2021-05-27 15:16:54,460: INFO/MainProcess] mingle: all alone
[2021-05-27 15:16:54,499: WARNING/MainProcess] /home/skydata/buy_it/env/lib/python3.8/site-packages/celery/fixups/django.py:205: UserWarning: Using settings.DEBUG leads to a memory
            leak, never use this setting in production environments!
  warnings.warn('''Using settings.DEBUG leads to a memory
[2021-05-27 15:16:54,499: INFO/MainProcess] celery@skydata-Latitude-E5430-non-vPro ready.
[2021-05-27 23:56:52,129: INFO/MainProcess] Received task: orders.tasks.order_created[96d43771-9a73-4e63-a1fd-2c31d372c063]  
[2021-05-27 23:56:59,049: ERROR/ForkPoolWorker-2] Task orders.tasks.order_created[96d43771-9a73-4e63-a1fd-2c31d372c063] raised unexpected: SMTPAuthenticationError(535, b'5.7.8 Username and Password not accepted. Learn more at\n5.7.8  https://support.google.com/mail/?p=BadCredentials k7sm5160881wro.8 - gsmtp')
Traceback (most recent call last):
  File "/home/skydata/buy_it/env/lib/python3.8/site-packages/celery/app/trace.py", line 412, in trace_task
    R = retval = fun(*args, **kwargs)
  File "/home/skydata/buy_it/env/lib/python3.8/site-packages/celery/app/trace.py", line 704, in __protected_call__
    return self.run(*args, **kwargs)
  File "/home/skydata/buy_it/src/orders/tasks.py", line 13, in order_created
    mail_sent = send_mail(subject, message, 'admin@buy_it.com', {order.email})
  File "/home/skydata/buy_it/env/lib/python3.8/site-packages/django/core/mail/__init__.py", line 61, in send_mail
    return mail.send()
  File "/home/skydata/buy_it/env/lib/python3.8/site-packages/django/core/mail/message.py", line 284, in send
    return self.get_connection(fail_silently).send_messages([self])
  File "/home/skydata/buy_it/env/lib/python3.8/site-packages/django/core/mail/backends/smtp.py", line 102, in send_messages
    new_conn_created = self.open()
  File "/home/skydata/buy_it/env/lib/python3.8/site-packages/django/core/mail/backends/smtp.py", line 69, in open
    self.connection.login(self.username, self.password)
  File "/usr/lib/python3.8/smtplib.py", line 734, in login
    raise last_exception
  File "/usr/lib/python3.8/smtplib.py", line 723, in login
    (code, resp) = self.auth(
  File "/usr/lib/python3.8/smtplib.py", line 646, in auth
    raise SMTPAuthenticationError(code, resp)
smtplib.SMTPAuthenticationError: (535, b'5.7.8 Username and Password not accepted. Learn more at\n5.7.8  https://support.google.com/mail/?p=BadCredentials k7sm5160881wro.8 - gsmtp')
[2021-05-28 00:00:41,979: INFO/MainProcess] Received task: orders.tasks.order_created[3bb32cf8-07e9-4da6-81e3-cc708db9c955]  
[2021-05-28 00:00:52,785: ERROR/ForkPoolWorker-2] Task orders.tasks.order_created[3bb32cf8-07e9-4da6-81e3-cc708db9c955] raised unexpected: SMTPAuthenticationError(535, b'5.7.8 Username and Password not accepted. Learn more at\n5.7.8  https://support.google.com/mail/?p=BadCredentials z9sm4691278wmi.17 - gsmtp')
Traceback (most recent call last):
  File "/home/skydata/buy_it/env/lib/python3.8/site-packages/celery/app/trace.py", line 412, in trace_task
    R = retval = fun(*args, **kwargs)
  File "/home/skydata/buy_it/env/lib/python3.8/site-packages/celery/app/trace.py", line 704, in __protected_call__
    return self.run(*args, **kwargs)
  File "/home/skydata/buy_it/src/orders/tasks.py", line 13, in order_created
    mail_sent = send_mail(subject, message, 'admin@buy_it.com', {order.email})
  File "/home/skydata/buy_it/env/lib/python3.8/site-packages/django/core/mail/__init__.py", line 61, in send_mail
    return mail.send()
  File "/home/skydata/buy_it/env/lib/python3.8/site-packages/django/core/mail/message.py", line 284, in send
    return self.get_connection(fail_silently).send_messages([self])
  File "/home/skydata/buy_it/env/lib/python3.8/site-packages/django/core/mail/backends/smtp.py", line 102, in send_messages
    new_conn_created = self.open()
  File "/home/skydata/buy_it/env/lib/python3.8/site-packages/django/core/mail/backends/smtp.py", line 69, in open
    self.connection.login(self.username, self.password)
  File "/usr/lib/python3.8/smtplib.py", line 734, in login
    raise last_exception
  File "/usr/lib/python3.8/smtplib.py", line 723, in login
    (code, resp) = self.auth(
  File "/usr/lib/python3.8/smtplib.py", line 646, in auth
    raise SMTPAuthenticationError(code, resp)
smtplib.SMTPAuthenticationError: (535, b'5.7.8 Username and Password not accepted. Learn more at\n5.7.8  https://support.google.com/mail/?p=BadCredentials z9sm4691278wmi.17 - gsmtp')
[2021-05-28 00:03:14,572: INFO/MainProcess] Received task: orders.tasks.order_created[0aaea519-3cc1-4dcc-b875-ac0e854f68bf]  
[2021-05-28 00:03:25,689: ERROR/ForkPoolWorker-2] Task orders.tasks.order_created[0aaea519-3cc1-4dcc-b875-ac0e854f68bf] raised unexpected: SMTPAuthenticationError(535, b'5.7.8 Username and Password not accepted. Learn more at\n5.7.8  https://support.google.com/mail/?p=BadCredentials b10sm5802486wrr.27 - gsmtp')
Traceback (most recent call last):
  File "/home/skydata/buy_it/env/lib/python3.8/site-packages/celery/app/trace.py", line 412, in trace_task
    R = retval = fun(*args, **kwargs)
  File "/home/skydata/buy_it/env/lib/python3.8/site-packages/celery/app/trace.py", line 704, in __protected_call__
    return self.run(*args, **kwargs)
  File "/home/skydata/buy_it/src/orders/tasks.py", line 13, in order_created
    mail_sent = send_mail(subject, message, 'admin@buy_it.com', {order.email})
  File "/home/skydata/buy_it/env/lib/python3.8/site-packages/django/core/mail/__init__.py", line 61, in send_mail
    return mail.send()
  File "/home/skydata/buy_it/env/lib/python3.8/site-packages/django/core/mail/message.py", line 284, in send
    return self.get_connection(fail_silently).send_messages([self])
  File "/home/skydata/buy_it/env/lib/python3.8/site-packages/django/core/mail/backends/smtp.py", line 102, in send_messages
    new_conn_created = self.open()
  File "/home/skydata/buy_it/env/lib/python3.8/site-packages/django/core/mail/backends/smtp.py", line 69, in open
    self.connection.login(self.username, self.password)
  File "/usr/lib/python3.8/smtplib.py", line 734, in login
    raise last_exception
  File "/usr/lib/python3.8/smtplib.py", line 723, in login
    (code, resp) = self.auth(
  File "/usr/lib/python3.8/smtplib.py", line 646, in auth
    raise SMTPAuthenticationError(code, resp)
smtplib.SMTPAuthenticationError: (535, b'5.7.8 Username and Password not accepted. Learn more at\n5.7.8  https://support.google.com/mail/?p=BadCredentials b10sm5802486wrr.27 - gsmtp')
[2021-05-28 00:06:22,806: INFO/MainProcess] Received task: orders.tasks.order_created[7d565267-3ec5-42c4-a6b4-d320ee7be56d]  
[2021-05-28 00:06:27,878: ERROR/ForkPoolWorker-2] Task orders.tasks.order_created[7d565267-3ec5-42c4-a6b4-d320ee7be56d] raised unexpected: SMTPAuthenticationError(535, b'5.7.8 Username and Password not accepted. Learn more at\n5.7.8  https://support.google.com/mail/?p=BadCredentials a4sm4496955wme.45 - gsmtp')
Traceback (most recent call last):
  File "/home/skydata/buy_it/env/lib/python3.8/site-packages/celery/app/trace.py", line 412, in trace_task
    R = retval = fun(*args, **kwargs)
  File "/home/skydata/buy_it/env/lib/python3.8/site-packages/celery/app/trace.py", line 704, in __protected_call__
    return self.run(*args, **kwargs)
  File "/home/skydata/buy_it/src/orders/tasks.py", line 13, in order_created
    mail_sent = send_mail(subject, message, 'admin@buy_it.com', {order.email})
  File "/home/skydata/buy_it/env/lib/python3.8/site-packages/django/core/mail/__init__.py", line 61, in send_mail
    return mail.send()
  File "/home/skydata/buy_it/env/lib/python3.8/site-packages/django/core/mail/message.py", line 284, in send
    return self.get_connection(fail_silently).send_messages([self])
  File "/home/skydata/buy_it/env/lib/python3.8/site-packages/django/core/mail/backends/smtp.py", line 102, in send_messages
    new_conn_created = self.open()
  File "/home/skydata/buy_it/env/lib/python3.8/site-packages/django/core/mail/backends/smtp.py", line 69, in open
    self.connection.login(self.username, self.password)
  File "/usr/lib/python3.8/smtplib.py", line 734, in login
    raise last_exception
  File "/usr/lib/python3.8/smtplib.py", line 723, in login
    (code, resp) = self.auth(
  File "/usr/lib/python3.8/smtplib.py", line 646, in auth
    raise SMTPAuthenticationError(code, resp)
smtplib.SMTPAuthenticationError: (535, b'5.7.8 Username and Password not accepted. Learn more at\n5.7.8  https://support.google.com/mail/?p=BadCredentials a4sm4496955wme.45 - gsmtp')
[2021-05-28 18:15:49,745: WARNING/MainProcess] consumer: Connection to broker lost. Trying to re-establish the connection...
Traceback (most recent call last):
  File "/home/skydata/buy_it/env/lib/python3.8/site-packages/celery/worker/consumer/consumer.py", line 318, in start
    blueprint.start(self)
  File "/home/skydata/buy_it/env/lib/python3.8/site-packages/celery/bootsteps.py", line 119, in start
    step.start(parent)
  File "/home/skydata/buy_it/env/lib/python3.8/site-packages/celery/worker/consumer/consumer.py", line 599, in start
    c.loop(*c.loop_args())
  File "/home/skydata/buy_it/env/lib/python3.8/site-packages/celery/worker/loops.py", line 83, in asynloop
    next(loop)
  File "/home/skydata/buy_it/env/lib/python3.8/site-packages/kombu/asynchronous/hub.py", line 364, in create_loop
    cb(*cbargs)
  File "/home/skydata/buy_it/env/lib/python3.8/site-packages/kombu/transport/base.py", line 238, in on_readable
    reader(loop)
  File "/home/skydata/buy_it/env/lib/python3.8/site-packages/kombu/transport/base.py", line 220, in _read
    drain_events(timeout=0)
  File "/home/skydata/buy_it/env/lib/python3.8/site-packages/amqp/connection.py", line 508, in drain_events
    while not self.blocking_read(timeout):
  File "/home/skydata/buy_it/env/lib/python3.8/site-packages/amqp/connection.py", line 514, in blocking_read
    return self.on_inbound_frame(frame)
  File "/home/skydata/buy_it/env/lib/python3.8/site-packages/amqp/method_framing.py", line 55, in on_frame
    callback(channel, method_sig, buf, None)
  File "/home/skydata/buy_it/env/lib/python3.8/site-packages/amqp/connection.py", line 520, in on_inbound_method
    return self.channels[channel_id].dispatch_method(
  File "/home/skydata/buy_it/env/lib/python3.8/site-packages/amqp/abstract_channel.py", line 145, in dispatch_method
    listener(*args)
  File "/home/skydata/buy_it/env/lib/python3.8/site-packages/amqp/connection.py", line 649, in _on_close
    self._x_close_ok()
  File "/home/skydata/buy_it/env/lib/python3.8/site-packages/amqp/connection.py", line 664, in _x_close_ok
    self.send_method(spec.Connection.CloseOk, callback=self._on_close_ok)
  File "/home/skydata/buy_it/env/lib/python3.8/site-packages/amqp/abstract_channel.py", line 59, in send_method
    conn.frame_writer(1, self.channel_id, sig, args, content)
  File "/home/skydata/buy_it/env/lib/python3.8/site-packages/amqp/method_framing.py", line 189, in write_frame
    write(view[:offset])
  File "/home/skydata/buy_it/env/lib/python3.8/site-packages/amqp/transport.py", line 305, in write
    self._write(s)
ConnectionResetError: [Errno 104] Connection reset by peer
[2021-05-28 18:15:51,651: ERROR/MainProcess] consumer: Cannot connect to amqp://guest:**@127.0.0.1:5672//: [Errno 111] Connection refused.
Trying again in 2.00 seconds... (1/100)

[2021-05-28 18:15:53,664: ERROR/MainProcess] consumer: Cannot connect to amqp://guest:**@127.0.0.1:5672//: [Errno 111] Connection refused.
Trying again in 4.00 seconds... (2/100)


worker: Warm shutdown (MainProcess)
 
 -------------- celery@skydata-Latitude-E5430-non-vPro v4.4.7 (cliffs)
--- ***** ----- 
-- ******* ---- Linux-5.4.0-70-generic-x86_64-with-glibc2.29 2021-05-27 15:16:53
- *** --- * --- 
- ** ---------- [config]
- ** ---------- .> app:         buy_it:0x7f3b8e454670
- ** ---------- .> transport:   amqp://guest:**@localhost:5672//
- ** ---------- .> results:     disabled://
- *** --- * --- .> concurrency: 4 (prefork)
-- ******* ---- .> task events: OFF (enable -E to monitor tasks in this worker)
--- ***** ----- 
 -------------- [queues]
                .> celery           exchange=celery(direct) key=celery
                

[tasks]
  . orders.tasks.order_created

[2021-05-30 10:44:00,640: INFO/MainProcess] Connected to amqp://guest:**@127.0.0.1:5672//
[2021-05-30 10:44:00,654: INFO/MainProcess] mingle: searching for neighbors
[2021-05-30 10:44:01,728: INFO/MainProcess] mingle: all alone
[2021-05-30 10:44:01,768: WARNING/MainProcess] /home/skydata/buy_it/env/lib/python3.8/site-packages/celery/fixups/django.py:205: UserWarning: Using settings.DEBUG leads to a memory
            leak, never use this setting in production environments!
  warnings.warn('''Using settings.DEBUG leads to a memory
[2021-05-30 10:44:01,769: INFO/MainProcess] celery@skydata-Latitude-E5430-non-vPro ready.

worker: Warm shutdown (MainProcess)
 
 -------------- celery@skydata-Latitude-E5430-non-vPro v4.4.7 (cliffs)
--- ***** ----- 
-- ******* ---- Linux-5.4.0-70-generic-x86_64-with-glibc2.29 2021-05-30 10:44:00
- *** --- * --- 
- ** ---------- [config]
- ** ---------- .> app:         buy_it:0x7ff4e9e71670
- ** ---------- .> transport:   amqp://guest:**@localhost:5672//
- ** ---------- .> results:     disabled://
- *** --- * --- .> concurrency: 4 (prefork)
-- ******* ---- .> task events: OFF (enable -E to monitor tasks in this worker)
--- ***** ----- 
 -------------- [queues]
                .> celery           exchange=celery(direct) key=celery
                

[tasks]
  . orders.tasks.order_created

[2021-05-30 20:52:07,832: INFO/MainProcess] Connected to amqp://guest:**@127.0.0.1:5672//
[2021-05-30 20:52:07,846: INFO/MainProcess] mingle: searching for neighbors
[2021-05-30 20:52:08,915: INFO/MainProcess] mingle: all alone
[2021-05-30 20:52:08,950: WARNING/MainProcess] /home/skydata/buy_it/env/lib/python3.8/site-packages/celery/fixups/django.py:205: UserWarning: Using settings.DEBUG leads to a memory
            leak, never use this setting in production environments!
  warnings.warn('''Using settings.DEBUG leads to a memory
[2021-05-30 20:52:08,950: INFO/MainProcess] celery@skydata-Latitude-E5430-non-vPro ready.
